Workbook

Sheet MAR.26
A1: S | B1: MAR/26 | E1: UTD JACOBINA | F1: QUADRO ENERG. | L1: PLANO 7 | M1: NÃO ATENDE UC | Q1: PINTAR DATA DE | AD1: PINTAR DE VERDE | AE1: =AE3/4 -> 160.25 | AF1: MÉDIA P/T | AG1: =AE3/12 -> 53.416667 | AH1: =AE3*2480 -> 1589680 | AT1: =AT2/10 -> 184608
A2: Contrato JACOBINA: | B2: 4600086370 | E2: =E3/B3 -> 0 | F2: CARTEIRA 2025 | L2: PLANO 14.4.12.1-LPT | M2: LPT DEFINITIVO - ATENDE UC | Q2: VERDE QUANDO | AD2: QUANDO LIGADOS | AE2: =AE3/B3 -> 16.435897 | AF2: =AF3/AE3 -> 0 | AG2: =AG3/AE3 -> 0 | AT2: =AE3*2880 -> 1846080 | AV2: =AE2*2480 -> 40761.026
A3: QTD. OBRAS | B3: =SUBTOTAL(3,B5:B98) -> 39 | L3: PLANO 14.7.3-LPT | M3: LPT PROVISÓRIO - TEM QUE VALIDAR UC | Q3: CRIADAS | AB3: TOTAIS: | AC3: =SUBTOTAL(9,AC5:AC98) -> 47 | AD3: =SUBTOTAL(9,AD5:AD98) -> 0 | AE3: =SUBTOTAL(9,AE5:AE98) -> 641 | AF3: =SUBTOTAL(9,AF5:AF98) -> 0 | AG3: =SUBTOTAL(9,AG5:AG98) -> 0 | AH3: =SUBTOTAL(9,AH5:AH98) -> 641 | AQ3: MAPA GERAL | AS3: =SUBTOTAL(9,AS5:AS98) -> 11853380 | AT3: =SUBTOTAL(9,AT5:AT98) -> 0 | AV3: =AE3*2480 -> 1589680 | AW3: =SUBTOTAL(9,AW5:AW98) -> 0 | AX3: =SUBTOTAL(9,AX5:AX98) -> 0
A4: NOTA | B4: PEP OBRA | C4: PEP KIT | D4: PEP MED | E4: TÍTULO | F4: MUNICIPIO | G4: STATUS DA OBRA | H4: OBS STATUS | I4: ENCARREGADO | J4: SUPERVISOR | K4: AR COELBA | L4: PLANO INVESTIMENTO | M4: CRITERIO | N4: VISITA PRÉVIA | O4: OBS. VISITA | P4: ANÁLISE PROJETO PRÉ-FECH. | Q4: SOLICITAÇÃO DE RESERVA | R4: DATA SAQUE MATERIAIS | S4: PES LV | T4: VENCIMENTO | U4: PES LM | V4: PES ENERGIZAÇÃO | W4: VENCIMENTO | X4: PES PD | Y4: DATA PD | Z4: STATUS PES PD | AA4: SI PG | AB4: PG's | AC4: CLIENTES PREVISTOS | AD4: QTD. UC'S VALIDADAS LPT | AE4: POSTES PREVISTOS | AF4: CAVA REALIZADA | AG4: POSTES REALIZADO | AH4: POSTES À IMPLANTA | AI4: AVNR | AJ4: AVNP | AK4: INCIO PREVISTO | AL4: FIM PREVISTO | AM4: REPROGRAMAÇÃO FIM | AN4: DATA ENERGIZAÇÃO REAL | AO4: OC DE ENERG. | AP4: PG REFERÊNCIA | AQ4: LATITUDE | AR4: LONGITUDE | AS4: VALOR DE PROJETO | AT4: VALOR DE SERVIÇO | AU4: CÓDIGO EQUIPE | AV4: PROVAVEL ROCHA | AW4: CABO 1B25 | AX4: CABO 3B35 | AY4: OBS | AZ4: AVALIAÇÃO SERVIÇO | BA4: SUBESTAÇÃO ALIMENTADOR | BB4: CHAVE PRINCIPAL | BC4: CHAVE PD | BD4: QTD. UC'S | BE4: VIP | BF4: QTD. H DP | BG4: CHI | BH4: LOCAIS ATINGIDOS | BI4: PG REFERÊNCIA | BJ4: SERVIÇO | BK4: RASCUNHO | BL4: DATA SAQUE MAT. LC | BM4: DATA EXECUÇÃO LC | BN4: TURMA LC | BO4: NÃO ELIMINAR ESTA COLUNA | BP4: NÃO ELIMINAR ESTA COLUNA | BQ4: NÃO ELIMINAR ESTA COLUNA | BR4: PROGRAMAÇÃO LV
A5: 9102043744 | B5: B-1136005 | E5: ER-CIND-FAZ-CANAVIAL-ITALEGRE | F5: BAIXA GRANDE | J5: =VLOOKUP(I5,DADOS!B:F,5,0) -> #N/A | L5: PLANO 14.7.3-LPT | M5: LPT | P5: 46066 | Q5: SOLICITAR | S5: N/A | T5: N/A | U5: N/A | V5: CRIAR | X5: N/A | AB5: E956768 AO E956772 | AC5: 3 | AE5: 5 | AH5: =AE5-AG5 -> 5 | AI5: =IF(OR(AE5=0, ISERR(AG5/AE5)), 0, AG5/AE5) -> 0 | AJ5: 1 | AP5: L432598 | AQ5: -11.961051 | AR5: -40.223323 | AS5: 34194.31 | AU5: =VLOOKUP(I5,DADOS!B:C,2,0) -> #N/A | AV5: =AE5*2480 -> 12400 | BA5: MUN-01N4 | BB5: T15928 | BG5: =BD5*BF5 -> 0 | BI5: L432598 | BJ5: ENCABEÇAR RD BT NO PG: L432598 E ENERGIZAR OBRA. | BK5: .
A6: 9101791472 | B6: B-1246148 | E6: RR-CIND-POV-BARRO VERMELHO-RURAL | F6: BAIXA GRANDE | J6: =VLOOKUP(I6,DADOS!B:F,5,0) -> #N/A | L6: PLANO 7 | M6: QLP | P6: 46070 | Q6: SOLICITAR | S6: CRIAR | U6: N/A | V6: CRIAR | X6: N/A | AA6: 1050244 | AB6: E974759 AO E974764/ E957969 AO E957972 | AC6: 1 | AE6: 10 | AH6: =AE6-AG6 -> 10 | AI6: =IF(OR(AE6=0, ISERR(AG6/AE6)), 0, AG6/AE6) -> 0 | AJ6: 1 | AP6: L434970 | AQ6: -11.976232 | AR6: -40.144518 | AS6: 73660.25 | AU6: =VLOOKUP(I6,DADOS!B:C,2,0) -> #N/A | AV6: =AE6*2480 -> 24800 | BA6: MUN-01N4 | BB6: H76119 | BG6: =BD6*BF6 -> 0 | BI6: L434970 | BJ6: INTERCALAR POSTE AT COM N1-3 ENTRE OS PG: L434970 - L434969, FECHAR CHAVE NOVA PRÓXIMO AO PG: L434970 E ENERGIZAR OBRA. | BK6: .
A7: 9102367761 | B7: B-1243250 | E7: ER-CIND-POV-CONCEICAO-CONCEICAO | F7: BAIXA GRANDE | J7: =VLOOKUP(I7,DADOS!B:F,5,0) -> #N/A | L7: PLANO 7 | M7: QLP | P7: 46064 | Q7: SOLICITAR | S7: CRIAR | U7: N/A | V7: CRIAR | X7: N/A | AB7: E956763 | AC7: 1 | AE7: 1 | AH7: =AE7-AG7 -> 1 | AI7: =IF(OR(AE7=0, ISERR(AG7/AE7)), 0, AG7/AE7) -> 0 | AJ7: 1 | AP7: D217416 | AQ7: -11.999163 | AR7: -40.121585 | AS7: 9994.23 | AU7: =VLOOKUP(I7,DADOS!B:C,2,0) -> #N/A | AV7: =AE7*2480 -> 2480 | BA7: MUN-01N4 | BB7: H80951 | BG7: =BD7*BF7 -> 0 | BI7: D217416 | BJ7: INTERCALAR POSTE AT COM N1 E TRAFO ENTRE OS PG: D217416 - D217415, FECHAR CHAVE NOVA PRÓXIMO AO PG: D217416 E ENERGIZAR OBRA. | BK7: .
A8: 9102126615 | B8: B-1161434 | E8: ER-CIND-FAZ-GENIPAPO-RURAL-BAIXA GRANDE | F8: BAIXA GRANDE | G8: RETIRADA DA CARTEIRA | H8: EM EXECUÇÃO DA CARTEIRA DE FEV/26. | J8: =VLOOKUP(I8,DADOS!B:F,5,0) -> #N/A | L8: PLANO 7 | M8: OUTROS | AC8: 0 | AE8: 12 | AH8: =AE8-AG8 -> 12 | AI8: =IF(OR(AE8=0, ISERR(AG8/AE8)), 0, AG8/AE8) -> 0 | AJ8: 1 | AS8: 5210.84 | AU8: =VLOOKUP(I8,DADOS!B:C,2,0) -> #N/A | AV8: =AE8*2480 -> 29760 | BG8: =BD8*BF8 -> 0 | BK8: .
A9: 9102344570 | B9: B-1238225 | C9: N/A | D9: N/A | E9: AL-MCM-01J5-CONSTR-ETAPA-1 | F9: MIGUEL CALMON | H9: OBRA AINDA SEM CARTEIRA DEFINIDA PROJETO REVISADO. CAMINHAMENTO EM CIRCUITO DUPLO. | J9: =VLOOKUP(I9,DADOS!B:F,5,0) -> #N/A | K9: NAILTON SANTANA PEREIRA FILHO - U344575 | L9: PLANO 1.2 | M9: AL/MELHORAMENTO | S9: CRIAR | V9: AGUARDANDO ANÁLISE | AA9: 1048504 | AB9: E958210 AO E958269 | AC9: 0 | AD9: 0 | AE9: =59-47 -> 12 | AH9: =AE9-AG9 -> 12 | AI9: =IF(OR(AE9=0, ISERR(AG9/AE9)), 0, AG9/AE9) -> 0 | AJ9: 0.7 | AP9: B355964 | AQ9: -11.403443 | AR9: -40.595049 | AS9: 835606.76 | AU9: =VLOOKUP(I9,DADOS!B:C,2,0) -> #N/A | AV9: =AE9*2480 -> 29760 | BA9: MCM-01J4 | BB9: G12584 | BG9: =BD9*BF9 -> 0 | BI9: B355964 | BK9: .
A10: 9102344571 | B10: B-1237604 | C10: N/A | D10: N/A | E10: AL-MCM-01J5-CONSTR-ETAPA-2 | F10: MIGUEL CALMON | H10: OBRA AINDA SEM CARTEIRA DEFINIDA | J10: =VLOOKUP(I10,DADOS!B:F,5,0) -> #N/A | K10: NAILTON SANTANA PEREIRA FILHO - U344575 | L10: PLANO 1.2 | M10: AL/MELHORAMENTO | P10: 46063 | Q10: SOLICITAR | S10: CRIAR | U10: N/A | V10: CRIAR | X10: CRIAR | AA10: 1048504 | AB10: E958270 AO E958379 | AC10: 0 | AD10: 0 | AE10: =107-1 -> 106 | AH10: =AE10-AG10 -> 106 | AI10: =IF(OR(AE10=0, ISERR(AG10/AE10)), 0, AG10/AE10) -> 0 | AJ10: 0.8 | AP10: R036999 | AQ10: -11.339545 | AR10: -40.609709 | AS10: 959254.78 | AU10: =VLOOKUP(I10,DADOS!B:C,2,0) -> #N/A | AV10: =AE10*2480 -> 262880 | BA10: MCM-01J4 | BB10: G12561 | BG10: =BD10*BF10 -> 0 | BI10: R034898 | BK10: .
A11: 9100619322 | B11: B-0649462 | E11: ME - ADF. POV. MAXIXE | F11: MIGUEL CALMON | J11: =VLOOKUP(I11,DADOS!B:F,5,0) -> #N/A | L11: PLANO 7 | M11: QLP | P11: 46065 | Q11: SOLICITAR | S11: CRIAR | U11: N/A | V11: =X11 -> CRIAR | X11: CRIAR | AC11: 0 | AE11: 1 | AH11: =AE11-AG11 -> 1 | AI11: =IF(OR(AE11=0, ISERR(AG11/AE11)), 0, AG11/AE11) -> 0 | AJ11: 1 | AP11: R032902 | AQ11: -11.470889 | AR11: -40.735028 | AS11: 13857.88 | AU11: =VLOOKUP(I11,DADOS!B:C,2,0) -> #N/A | AV11: =AE11*2480 -> 2480 | BA11: MCM-01J3 | BB11: J08303 | BG11: =BD11*BF11 -> 0 | BI11: R032902 | BJ11: ADICIONAR FASE DO PG: R032902 AO R031899, INTERCALAR PT AT C/ N4 CFU ENTRE OS PG: R031909 - E ENERGIZAR OBRA. | BK11: 2026-23653
A12: 9101196119 | B12: B-0879015 | E12: MP-CIND-POV LAGOA GRANDE-RURAL-MGC | F12: MIGUEL CALMON | G12: CANCELADA | H12: OBRA JÁ EXECUTADA ATRAVÉS DO PROJETO Y-0982612 - MP - CCOL - POV. LAGOA GRANDE - RURAL - MIGUEL CALMON LAUDO DE CANCELAMENTO NO GEOEB | J12: =VLOOKUP(I12,DADOS!B:F,5,0) -> #N/A | L12: PLANO 14.4.12.1-LPT | M12: AIC AUDITORIA | AC12: 1 | AE12: 9 | AH12: =AE12-AG12 -> 9 | AI12: =IF(OR(AE12=0, ISERR(AG12/AE12)), 0, AG12/AE12) -> 0 | AJ12: 1 | AS12: 33926.81 | AU12: =VLOOKUP(I12,DADOS!B:C,2,0) -> #N/A | AV12: =AE12*2480 -> 22320 | BG12: =BD12*BF12 -> 0 | BK12: .
A13: 9101982739 | B13: B-1115207 | E13: AC-CIND-POV-MOCAMBO | F13: MIGUEL CALMON | G13: RETIRADA DA CARTEIRA | H13: RETIRADA DA CARTEIRA PELA COELBA - FALTA DE MATERIAIS REGULARIZAÇÃO DE MEDIDOR AO TEMPO | J13: =VLOOKUP(I13,DADOS!B:F,5,0) -> #N/A | L13: PLANO 7 | M13: QLP | S13: CRIAR | U13: N/A | V13: CRIAR | X13: N/A | AC13: 4 | AE13: 1 | AH13: =AE13-AG13 -> 1 | AI13: =IF(OR(AE13=0, ISERR(AG13/AE13)), 0, AG13/AE13) -> 0 | AJ13: 1 | AP13: R030542 | AQ13: -11.2871714 | AR13: -40.8255382 | AS13: 20973.08 | AU13: =VLOOKUP(I13,DADOS!B:C,2,0) -> #N/A | AV13: =AE13*2480 -> 2480 | BG13: =BD13*BF13 -> 0 | BK13: .
A14: 9102140924 | B14: B-1176892 | E14: AC-CIND-POV-CAMPO DA SILVA -RURAL | F14: MIGUEL CALMON | H14: REGULARIZAÇÃO DE MEDIDOR AO TEMPO | J14: =VLOOKUP(I14,DADOS!B:F,5,0) -> #N/A | L14: PLANO 7 | M14: QLP | P14: 46065 | Q14: SOLICITAR | S14: N/A | T14: N/A | U14: N/A | V14: CRIAR | X14: N/A | AB14: E956764 e E956765 | AC14: 1 | AE14: 2 | AH14: =AE14-AG14 -> 2 | AI14: =IF(OR(AE14=0, ISERR(AG14/AE14)), 0, AG14/AE14) -> 0 | AJ14: 1 | AP14: B539332 | AQ14: -11.427130 | AR14: -40.503445 | AS14: 16832.17 | AU14: =VLOOKUP(I14,DADOS!B:C,2,0) -> #N/A | AV14: =AE14*2480 -> 4960 | BA14: MCM-01J2 | BB14: J12992 | BG14: =BD14*BF14 -> 0 | BI14: B539332 | BJ14: ENCABEÇAR RD BT NO PG: B539332 E ENERGIZAR OBRA. | BK14: .
A15: 9102368609 | B15: B-1238780 | E15: ER-SEIN-RUA-TAMANCO 1800-CURRAL VELHO | F15: MIGUEL CALMON | G15: RETIRADA DA CARTEIRA | H15: ANTECIPADA PARA FEV/26 OBRA SERÁ EXECUTADA NA CARTEIRA DE FEV/26 | J15: =VLOOKUP(I15,DADOS!B:F,5,0) -> #N/A | L15: PLANO 7 | M15: GOVERNO | AC15: 10 | AE15: 99 | AH15: =AE15-AG15 -> 99 | AI15: =IF(OR(AE15=0, ISERR(AG15/AE15)), 0, AG15/AE15) -> 0 | AJ15: 0.5 | AS15: 730549.03 | AU15: =VLOOKUP(I15,DADOS!B:C,2,0) -> #N/A | AV15: =AE15*2480 -> 245520 | BG15: =BD15*BF15 -> 0 | BK15: .
A16: 9102361558 | B16: B-1235157 | E16: RR-CIND-POV-MACAUBAS 53-RURAL MOD | F16: MIGUEL CALMON | J16: =VLOOKUP(I16,DADOS!B:F,5,0) -> #N/A | L16: PLANO 7 | M16: QLP | P16: 46065 | Q16: SOLICITAR | S16: CRIAR | U16: CRIAR | V16: CRIAR | X16: N/A | AA16: 1050249 | AB16: E974603 AO E974665 | AC16: 1 | AE16: 69 | AH16: =AE16-AG16 -> 69 | AI16: =IF(OR(AE16=0, ISERR(AG16/AE16)), 0, AG16/AE16) -> 0 | AJ16: 1 | AP16: E388736 | AQ16: -11.373322 | AR16: -40.783204 | AS16: 327676.8 | AU16: =VLOOKUP(I16,DADOS!B:C,2,0) -> #N/A | AV16: =AE16*2480 -> 171120 | BA16: MCM-01J3 | BB16: V02731 | BG16: =BD16*BF16 -> 0 | BI16: B992842 | BJ16: ALTERAR ESTRUTURA DE N3 P/ N4 NO PG: B992842, FECHAR CHAVE NOVA PRÓXIMO AO PG: B992842 E ENERGIZAR OBRA. | BK16: 2026-23655
A17: 9101989375 | B17: B-1120297 | E17: IS-COEL-AV-ODONEL RIOS-CENTRO-MIG CALMON | F17: MIGUEL CALMON | H17: MELHORAMENTO // OBRA URBANA // NO CENTRO | J17: =VLOOKUP(I17,DADOS!B:F,5,0) -> #N/A | L17: PLANO 8 | M17: INTERV. DE SEGURANÇA | O17: MELHORAMENTO // OBRA URBANA // NO CENTRO | AA17: CRIAR | AC17: 0 | AE17: 12 | AH17: =AE17-AG17 -> 12 | AI17: =IF(OR(AE17=0, ISERR(AG17/AE17)), 0, AG17/AE17) -> 0 | AJ17: 1 | AP17: R032031 | AQ17: -11.4312542 | AR17: -40.5955886 | AS17: 136273.14 | AU17: =VLOOKUP(I17,DADOS!B:C,2,0) -> #N/A | AV17: =AE17*2480 -> 29760 | BG17: =BD17*BF17 -> 0 | BK17: .
A18: 9101088753 | B18: B-0816186 | E18: ME-CIND-POV. CABORONGA-RURAL ADF | F18: MIGUEL CALMON | G18: RETIRADA DA CARTEIRA | H18: SEM PROJETO MAGNÉTICO NEM LEVANTAMENTO NO GEOEX. | J18: =VLOOKUP(I18,DADOS!B:F,5,0) -> #N/A | L18: PLANO 7 | M18: OUTROS | AC18: 0 | AE18: 0 | AH18: =AE18-AG18 -> 0 | AI18: =IF(OR(AE18=0, ISERR(AG18/AE18)), 0, AG18/AE18) -> 0 | AJ18: 1 | AS18: 5210.84 | AU18: =VLOOKUP(I18,DADOS!B:C,2,0) -> #N/A | AV18: =AE18*2480 -> 0 | BG18: =BD18*BF18 -> 0 | BK18: .
A19: 9102146204 | B19: B-1173379 | E19: ER-CIND-RUA-VARZEA DOS BOIS-CENTRO | F19: MIGUEL CALMON | G19: RETIRADA DA CARTEIRA | H19: EM EXECUÇÃO DA CARTEIRA DE FEV/26. | J19: =VLOOKUP(I19,DADOS!B:F,5,0) -> #N/A | L19: PLANO 7 | M19: OUTROS | AC19: 0 | AE19: 11 | AH19: =AE19-AG19 -> 11 | AI19: =IF(OR(AE19=0, ISERR(AG19/AE19)), 0, AG19/AE19) -> 0 | AJ19: 1 | AS19: 5210.84 | AU19: =VLOOKUP(I19,DADOS!B:C,2,0) -> #N/A | AV19: =AE19*2480 -> 27280 | BG19: =BD19*BF19 -> 0 | BK19: .
A20: 9101992115 | B20: B-1120112 | E20: LD CIND FAZ TANQUE NOVO RURAL | F20: MUNDO NOVO | G20: RETIRADA DA CARTEIRA | H20: RETIRADA DA CARTEIRA PELA COELBA - FALTA DE MATERIAIS VERIFICAR SE TEM ACESSO PARA CAMINHÃO LV. | J20: =VLOOKUP(I20,DADOS!B:F,5,0) -> #N/A | L20: PLANO 14.7.3-LPT | M20: AIC AUDITORIA | P20: 46063 | Q20: SOLICITAR | S20: CRIAR | U20: N/A | V20: CRIAR | X20: N/A | AC20: 1 | AE20: 3 | AH20: =AE20-AG20 -> 3 | AI20: =IF(OR(AE20=0, ISERR(AG20/AE20)), 0, AG20/AE20) -> 0 | AJ20: 1 | AP20: L392615 | AQ20: -12.071877 | AR20: -40.461241 | AS20: 60968.17 | AU20: =VLOOKUP(I20,DADOS!B:C,2,0) -> #N/A | AV20: =AE20*2480 -> 7440 | BG20: =BD20*BF20 -> 0 | BI20: L392615 | BK20: .
A21: 9102005076 | B21: B-1119761 | E21: IE-GRUA FAZ.ALTO ALEGRE MOOD-RURAL | F21: MUNDO NOVO | H21: INST. RELIGADOR DE LINHA | J21: =VLOOKUP(I21,DADOS!B:F,5,0) -> #N/A | M21: AIC AUDITORIA | S21: CRIAR | V21: AGUARDANDO ANÁLISE | AC21: 0 | AE21: 0 | AH21: =AE21-AG21 -> 0 | AI21: =IF(OR(AE21=0, ISERR(AG21/AE21)), 0, AG21/AE21) -> 0 | AJ21: 1 | AP21: D262200 | AQ21: -11.862749 | AR21: -40.487260 | AS21: 99015.22 | AU21: =VLOOKUP(I21,DADOS!B:C,2,0) -> #N/A | AV21: =AE21*2480 -> 0 | BG21: =BD21*BF21 -> 0 | BI21: D262200 | BK21: .
A22: 9101893077 | B22: B-1072445 | C22: B-1141998 | D22: B-1141997 | E22: ER-CIND-FAZ-UMBUZEIRO-RURAL | F22: MUNDO NOVO | G22: RETIRADA DA CARTEIRA | H22: RETIRADA DA CARTEIRA PELA COELBA - FALTA DE MATERIAIS | J22: =VLOOKUP(I22,DADOS!B:F,5,0) -> #N/A | K22: NAILTON SANTANA PEREIRA FILHO - U344575 | L22: PLANO 14.7.3-LPT | M22: QLP | N22: 46010 | P22: 45993 | Q22: 45993 | S22: CRIAR | U22: N/A | V22: CRIAR | X22: N/A | AB22: E933036 AO E933044 | AC22: 1 | AE22: 9 | AH22: =AE22-AG22 -> 9 | AI22: =IF(OR(AE22=0, ISERR(AG22/AE22)), 0, AG22/AE22) -> 0 | AJ22: 1 | AP22: D548038 | AQ22: -11,666902 | AR22: -40,380120 | AS22: 36023.21 | AU22: =VLOOKUP(I22,DADOS!B:C,2,0) -> #N/A | AV22: =AE22*2480 -> 22320 | BA22: MUN-01N6 2#4 | BB22: W65651 | BG22: 0 | BI22: D548038 | BJ22: INTERCALAR POSTE AT COM N1-3 ENTRE OS PG: D548039 - D548038, FECHAR CHAVE NOVA PRÓBIMO AO PG: D548038 E ENERGIZAR OBRA. | BK22: .
A23: 9101866308 | B23: B-1063581 | E23: ER-CIND-RUA-JEQUITIBA-RURAL | F23: MUNDO NOVO | G23: RETIRADA DA CARTEIRA | H23: RETIRADA DA CARTEIRA PELA COELBA - FALTA DE MATERIAIS | J23: =VLOOKUP(I23,DADOS!B:F,5,0) -> #N/A | L23: PLANO 14.7.3-LPT | M23: QLP | P23: 46062 | Q23: SOLICITAR | S23: CRIAR | U23: N/A | V23: CRIAR | X23: N/A | AB23: E956729 AO E956732 | AC23: 2 | AE23: 4 | AH23: =AE23-AG23 -> 4 | AI23: =IF(OR(AE23=0, ISERR(AG23/AE23)), 0, AG23/AE23) -> 0 | AJ23: 1 | AP23: D715524 | AQ23: -12.053776 | AR23: -40.496625 | AS23: 22022.48 | AU23: =VLOOKUP(I23,DADOS!B:C,2,0) -> #N/A | AV23: =AE23*2480 -> 9920 | BG23: =BD23*BF23 -> 0 | BI23: D715524 | BK23: .
A24: 9101722770 | B24: B-1009274 | E24: IE-REGULADOR-MUN-01N5-T20539 | F24: MUNDO NOVO | H24: INST. REGULADORES | J24: =VLOOKUP(I24,DADOS!B:F,5,0) -> #N/A | M24: INTERV. DE SEGURANÇA | S24: CRIAR | U24: N/A | V24: AGUARDANDO ANÁLISE | X24: N/A | AC24: 0 | AE24: 3 | AH24: =AE24-AG24 -> 3 | AI24: =IF(OR(AE24=0, ISERR(AG24/AE24)), 0, AG24/AE24) -> 0 | AJ24: 0.8 | AP24: L276481 | AQ24: -11.809883 | AR24: -40.436864 | AS24: 659578.14 | AU24: =VLOOKUP(I24,DADOS!B:C,2,0) -> #N/A | AV24: =AE24*2480 -> 7440 | BG24: =BD24*BF24 -> 0 | BI24: L276481 | BK24: .
A25: 9102369819 | B25: B-1244188 | E25: ER-CIND-POV-BURRO BOM-RURAL | F25: MUNDO NOVO | J25: =VLOOKUP(I25,DADOS!B:F,5,0) -> #N/A | L25: PLANO 7 | M25: QLP | P25: 46066 | Q25: SOLICITAR | S25: CRIAR | U25: N/A | V25: CRIAR | X25: N/A | AA25: 1050250 | AB25: E974673 AO E974692 | AC25: 1 | AE25: 19 | AH25: =AE25-AG25 -> 19 | AI25: =IF(OR(AE25=0, ISERR(AG25/AE25)), 0, AG25/AE25) -> 0 | AJ25: 1 | AP25: A467929 | AQ25: -12.080572 | AR25: -40.822991 | AS25: 107543.86 | AU25: =VLOOKUP(I25,DADOS!B:C,2,0) -> #N/A | AV25: =AE25*2480 -> 47120 | BA25: TPM-01Z1 | BB25: H32986 | BG25: =BD25*BF25 -> 0 | BI25: A467929 | BJ25: INTERCALAR POSTE AT COM N1-3 ENTRE OS PG: A467930 - A467929, FECHAR CHAVE NOVA PRÓXIMO AO PG: A467930 E ENERGIZAR OBRA. | BK25: 2026-23656
A26: 9102368366 | B26: B-1244550 | E26: ER-CIND-FAZ-LAGOA DO MILHO-LAGOA DO MILH | F26: MUNDO NOVO | J26: =VLOOKUP(I26,DADOS!B:F,5,0) -> #N/A | L26: PLANO 7 | M26: QLP | P26: 46066 | Q26: SOLICITAR | S26: CRIAR | U26: N/A | V26: CRIAR | X26: N/A | AC26: 1 | AE26: 2 | AH26: =AE26-AG26 -> 2 | AI26: =IF(OR(AE26=0, ISERR(AG26/AE26)), 0, AG26/AE26) -> 0 | AJ26: 1 | AS26: 27311.96 | AU26: =VLOOKUP(I26,DADOS!B:C,2,0) -> #N/A | AV26: =AE26*2480 -> 4960 | BA26: MUN-01N6 | BB26: W11832 | BG26: =BD26*BF26 -> 0 | BI26: D244767 | BJ26: INTERCALAR POSTE AT COM N1 E TRAFO ENTRE OS PG: D244767 - D244768, FECHAR CHAVE NOVA PRÓXIMO AO PG: D244767 E ENERGIZAR OBRA. | BK26: 2026-23658
A27: 9102363948 | B27: B-1242264 | E27: ER-CIND-POV-DE IBIAPORA 135-RURAL | F27: MUNDO NOVO | J27: =VLOOKUP(I27,DADOS!B:F,5,0) -> #N/A | L27: PLANO 7 | M27: QLP | P27: 46066 | Q27: SOLICITAR | S27: CRIAR | U27: N/A | V27: CRIAR | X27: N/A | AA27: 1050251 | AB27: E974693 AO E974715 | AC27: 1 | AE27: 23 | AH27: =AE27-AG27 -> 23 | AI27: =IF(OR(AE27=0, ISERR(AG27/AE27)), 0, AG27/AE27) -> 0 | AJ27: 1 | AP27: D093566 | AQ27: -12.037555 | AR27: -40.835501 | AS27: 212803.12 | AU27: =VLOOKUP(I27,DADOS!B:C,2,0) -> #N/A | AV27: =AE27*2480 -> 57040 | BA27: TPM-01Z1 | BB27: W51280 | BG27: =BD27*BF27 -> 0 | BI27: D093566 | BJ27: INTERCALAR POSTE AT COM N1-3 ENTRE OS PG: D093566 - D093567, FECHAR CHAVE NOVA PRÓXIMO AO PG: D093567 E ENERGIZAR OBRA. | BK27: 2026-23660
A28: 9102382526 | B28: B-1244752 | E28: ER-CIND-TRV-DO COLEGIO-RURAL | F28: MUNDO NOVO | J28: =VLOOKUP(I28,DADOS!B:F,5,0) -> #N/A | L28: PLANO 7 | M28: QLP | P28: 46066 | Q28: SOLICITAR | S28: CRIAR | U28: N/A | V28: =X28 -> CRIAR | X28: CRIAR | AC28: 1 | AE28: 0 | AH28: =AE28-AG28 -> 0 | AI28: =IF(OR(AE28=0, ISERR(AG28/AE28)), 0, AG28/AE28) -> 0 | AJ28: 1 | AP28: D383767 | AQ28: -11.671931 | AR28: -40.371607 | AS28: 25596.67 | AU28: =VLOOKUP(I28,DADOS!B:C,2,0) -> #N/A | AV28: =AE28*2480 -> 0 | BA28: MUN-01N6 | BB28: W11832 | BG28: =BD28*BF28 -> 0 | BI28: D383767 | BJ28: ABRIR CHAVE: N02285 P/ ADICIONAR FASE DO PG: D535239 AO D535237, SUBST. TF: N12476, SUBST. RD BT AT O PG: D535237 E ENERGIZAR OBRA. | BK28: CRIAR
A29: 9102374555 | B29: B-1239657 | E29: AC-CCOL-FAZ-NOVA FLORESTA-RURAL MOD | F29: OUROLÂNDIA | G29: RETIRADA DA CARTEIRA | H29: SEM PROJETO MAGNÉTICO NO GEOEX, APENAS LEVANTAMENTO. | J29: =VLOOKUP(I29,DADOS!B:F,5,0) -> #N/A | L29: PLANO 7 | M29: REPUTACIONAL | AC29: 0 | AE29: 0 | AH29: =AE29-AG29 -> 0 | AI29: =IF(OR(AE29=0, ISERR(AG29/AE29)), 0, AG29/AE29) -> 0 | AJ29: 0.3 | AS29: 4996248.4 | AU29: =VLOOKUP(I29,DADOS!B:C,2,0) -> #N/A | AV29: =AE29*2480 -> 0 | BG29: =BD29*BF29 -> 0 | BK29: .
A30: 9102378653 | B30: B-1244900 | E30: AC-CIND-RUA-FLORISVALDO L DE OLI-CENTRO | F30: OUROLÂNDIA | J30: =VLOOKUP(I30,DADOS!B:F,5,0) -> #N/A | L30: PLANO 7 | M30: QLP | P30: 46066 | Q30: SOLICITAR | S30: N/A | T30: N/A | U30: N/A | V30: CRIAR | X30: N/A | AC30: 4 | AE30: 2 | AH30: =AE30-AG30 -> 2 | AI30: =IF(OR(AE30=0, ISERR(AG30/AE30)), 0, AG30/AE30) -> 0 | AJ30: 1 | AP30: B923188 | AQ30: -10.854303 | AR30: -41.379159 | AS30: 11763.77 | AU30: =VLOOKUP(I30,DADOS!B:C,2,0) -> #N/A | AV30: =AE30*2480 -> 4960 | BA30: OUL-01M1 | BB30: H63358 | BG30: =BD30*BF30 -> 0 | BI30: B923188 | BJ30: ENCABEÇAR RD BT NO PG: B923188 E ENERGIZAR OBRA. | BK30: .
A31: 9102042535 | B31: B-1130735 | E31: ER-CCOL-POV-VERDADEIRA-VERDADEIRA | F31: UMBURANAS | G31: RETIRADA DA CARTEIRA | H31: RETIRADA DA CARTEIRA PELA COELBA - FALTA DE MATERIAIS | J31: =VLOOKUP(I31,DADOS!B:F,5,0) -> #N/A | L31: PLANO 14.7.3-LPT | M31: LPT | S31: CRIAR | U31: N/A | V31: CRIAR | X31: N/A | AA31: CRIAR | AC31: 2 | AE31: 7 | AH31: =AE31-AG31 -> 7 | AI31: =IF(OR(AE31=0, ISERR(AG31/AE31)), 0, AG31/AE31) -> 0 | AJ31: 1 | AS31: 50882.07 | AU31: =VLOOKUP(I31,DADOS!B:C,2,0) -> #N/A | AV31: =AE31*2480 -> 17360 | BG31: =BD31*BF31 -> 0 | BK31: .
A32: 9102036707 | B32: B-1132638 | E32: ER-CIND-POV-SAO JOSE-RURAL | F32: UMBURANAS | J32: =VLOOKUP(I32,DADOS!B:F,5,0) -> #N/A | L32: PLANO 14.4.12.1-LPT | M32: LPT | P32: 46065 | Q32: SOLICITAR | S32: CRIAR | U32: N/A | V32: CRIAR | X32: N/A | AB32: E956775 AO E956777 | AC32: 1 | AE32: 3 | AH32: =AE32-AG32 -> 3 | AI32: =IF(OR(AE32=0, ISERR(AG32/AE32)), 0, AG32/AE32) -> 0 | AJ32: 1 | AS32: 23944.89 | AU32: =VLOOKUP(I32,DADOS!B:C,2,0) -> #N/A | AV32: =AE32*2480 -> 7440 | BA32: UBR-01C1 | BB32: J59389 | BG32: =BD32*BF32 -> 0 | BI32: D103574 | BJ32: INTERCALAR POSTE AT COM N1 ENTRE OS PG: D103574 - D103578, ENCABEÇAR RD BT NO PG: R071904 E ENERGIZAR OBRA. | BK32: CRIAR
A33: 9102332784 | B33: B-1222009 | E33: MP-CIND-POV-ANGICAL-VERDADEIRA | F33: UMBURANAS | J33: =VLOOKUP(I33,DADOS!B:F,5,0) -> #N/A | L33: PLANO 14.4.12.1-LPT | M33: LPT | P33: 46066 | Q33: SOLICITAR | S33: CRIAR | U33: CRIAR | V33: =X33 -> CRIAR | X33: CRIAR | AA33: 1050252 | AB33: E974716 AO E974725 | AC33: 1 | AE33: 10 | AH33: =AE33-AG33 -> 10 | AI33: =IF(OR(AE33=0, ISERR(AG33/AE33)), 0, AG33/AE33) -> 0 | AJ33: 1 | AS33: 85055.68 | AU33: =VLOOKUP(I33,DADOS!B:C,2,0) -> #N/A | AV33: =AE33*2480 -> 24800 | BA33: UBR-01C1 | BB33: V35044 | BG33: =BD33*BF33 -> 0 | BI33: E106998 | BJ33: MONTAR BANCADA COM N3 NO PG: E106998 E ENERGIZAR OBRA. | BK33: CRIAR
A34: 9102295522 | B34: B-1208480 | E34: ER-CIND-POV-POTES 5528-POTES MOD | F34: UMBURANAS | G34: RETIRADA DA CARTEIRA | H34: SEM PROJETO MAGNÉTICO NO GEOEX, APENAS LEVANTAMENTO. | J34: =VLOOKUP(I34,DADOS!B:F,5,0) -> #N/A | L34: PLANO 14.4.12.1-LPT | M34: QLP | AC34: 3 | AE34: 0 | AH34: =AE34-AG34 -> 0 | AI34: =IF(OR(AE34=0, ISERR(AG34/AE34)), 0, AG34/AE34) -> 0 | AJ34: 1 | AS34: 131070.72 | AU34: =VLOOKUP(I34,DADOS!B:C,2,0) -> #N/A | AV34: =AE34*2480 -> 0 | BG34: =BD34*BF34 -> 0 | BK34: .
A35: 9102364278 | B35: B-1238566 | E35: ER-CIND-POV-VARZEA DE DENTRO-DELFINO-MOD | F35: UMBURANAS | G35: RETIRADA DA CARTEIRA | H35: SEM PROJETO MAGNÉTICO NO GEOEX, APENAS LEVANTAMENTO. | J35: =VLOOKUP(I35,DADOS!B:F,5,0) -> #N/A | L35: PLANO 7 | M35: QLP | AC35: 1 | AE35: 140 | AH35: =AE35-AG35 -> 140 | AI35: =IF(OR(AE35=0, ISERR(AG35/AE35)), 0, AG35/AE35) -> 0 | AJ35: 1 | AS35: 732685.33 | AU35: =VLOOKUP(I35,DADOS!B:C,2,0) -> #N/A | AV35: =AE35*2480 -> 347200 | BG35: =BD35*BF35 -> 0 | BK35: .
A36: 9102344574 | B36: B-1246232 | E36: AL-SE-UBR-AMPLIA O-R026798 | F36: UMBURANAS | H36: INTERVENÇÃO DE LV DENTRO SE UBR-01C1 | J36: =VLOOKUP(I36,DADOS!B:F,5,0) -> #N/A | L36: PLANO 1 | M36: AL/MELHORAMENTO | AC36: 0 | AE36: 11 | AH36: =AE36-AG36 -> 11 | AI36: =IF(OR(AE36=0, ISERR(AG36/AE36)), 0, AG36/AE36) -> 0 | AJ36: 0.7 | AP36: D702302 | AQ36: -10.71903532 | AR36: -41.31470695 | AS36: 788826.74 | AU36: =VLOOKUP(I36,DADOS!B:C,2,0) -> #N/A | AV36: =AE36*2480 -> 27280 | BG36: =BD36*BF36 -> 0 | BI36: D702302 | BK36: .
A37: 9102375704 | B37: B-1244756 | E37: ER-CIND-POV-VARZEA DE DENTRO-RURAL | F37: UMBURANAS | J37: =VLOOKUP(I37,DADOS!B:F,5,0) -> #N/A | L37: PLANO 7 | M37: QLP | S37: CRIAR | U37: N/A | V37: CRIAR | X37: N/A | AA37: 1050253 | AB37: E974726 AO E974758 | AC37: 0 | AE37: 33 | AH37: =AE37-AG37 -> 33 | AI37: =IF(OR(AE37=0, ISERR(AG37/AE37)), 0, AG37/AE37) -> 0 | AJ37: 1 | AP37: R071827 | AQ37: -10.274730 | AR37: -41.042781 | AS37: 220686.32 | AU37: =VLOOKUP(I37,DADOS!B:C,2,0) -> #N/A | AV37: =AE37*2480 -> 81840 | BA37: UBR-01C1 | BB37: J08479 | BG37: =BD37*BF37 -> 0 | BI37: R071827 | BJ37: INTERCALAR POSTE AT COM N1-3 ENTRE OS PG: R071827 - R071828, FECHAR CHAVE NOVA PRÓXIMO AO PG: R071827 E ENERGIZAR OBRA. | BK37: CRIAR
A38: 9102140198 | B38: B-1168420 | E38: ER-CIND-POV-ABENGOADA 4444-RURAL V NOVA | F38: VÁRZEA NOVA | J38: =VLOOKUP(I38,DADOS!B:F,5,0) -> #N/A | L38: PLANO 14.7.3-LPT | M38: LPT | S38: N/A | T38: N/A | U38: N/A | V38: CRIAR | X38: N/A | AC38: 1 | AE38: 0 | AH38: =AE38-AG38 -> 0 | AI38: =IF(OR(AE38=0, ISERR(AG38/AE38)), 0, AG38/AE38) -> 0 | AJ38: 1 | AP38: E517384 | AQ38: -11.013217 | AR38: -41.163311 | AS38: 6434.97 | AU38: =VLOOKUP(I38,DADOS!B:C,2,0) -> #N/A | AV38: =AE38*2480 -> 0 | BA38: JCB-09N4 | BB38: D00497 | BG38: =BD38*BF38 -> 0 | BI38: E517384 | BJ38: ENCABEÇAR RD BT NO PG: E517380 E ENERGIZAR OBRA. | BK38: .
A39: 9101828084 | B39: B-1047990 | E39: AC-CIND-POV-MOCOZEIRA 180-RURAL | F39: VÁRZEA NOVA | G39: CANCELADA | H39: ADF DE 1,8KM E SUBST. TRAFO 2F-10KVA POR 3F-30KVA OBRA JÁ CONSTRUÍDA ATRAVÉS DO PROJETO: B-1135277 - AC-CIND-POV-MOCOZEIRA-RURAL - VÁRZEA NOVA | J39: =VLOOKUP(I39,DADOS!B:F,5,0) -> #N/A | L39: PLANO 7 | M39: QLP | U39: N/A | V39: =X39 | AC39: 1 | AE39: 0 | AH39: =AE39-AG39 -> 0 | AI39: =IF(OR(AE39=0, ISERR(AG39/AE39)), 0, AG39/AE39) -> 0 | AJ39: 1 | AP39: D738542 | AQ39: -11.247387 | AR39: -40.996289 | AS39: 16960.43 | AU39: =VLOOKUP(I39,DADOS!B:C,2,0) -> #N/A | AV39: =AE39*2480 -> 0 | BG39: =BD39*BF39 -> 0 | BI39: D738542 | BK39: .
A40: 9101877529 | B40: B-1063724 | E40: AC-CIND-FAZ-NOVA CONCEICAO-NOVA CONCEICA | F40: VÁRZEA NOVA | H40: SUBST. CABO BT 2B35 POR 3B35 | J40: =VLOOKUP(I40,DADOS!B:F,5,0) -> #N/A | L40: PLANO 7 | M40: QLP | S40: CRIAR | U40: N/A | V40: =X40 -> CRIAR | X40: CRIAR | AC40: 1 | AE40: 0 | AH40: =AE40-AG40 -> 0 | AI40: =IF(OR(AE40=0, ISERR(AG40/AE40)), 0, AG40/AE40) -> 0 | AJ40: 1 | AP40: D285034 | AQ40: -11.127288 | AR40: -40.931057 | AS40: 17303.96 | AU40: =VLOOKUP(I40,DADOS!B:C,2,0) -> #N/A | AV40: =AE40*2480 -> 0 | BA40: MCH-01C2 | BB40: W00239 | BG40: =BD40*BF40 -> 0 | BI40: D285034 | BJ40: ADICIONAR +1 ESTRIBO E +1 CHAVE NO PG: D285032 E ENERGIZAR OBRA. | BK40: CRIAR
...

Sheet FEV.26
A1: CARTEIRA: | B1: C | E1: UTD JACOBINA | F1: QUADRO ENERG. | L1: PLANO 7 | M1: NÃO ATENDE UC | Q1: PINTAR DATA DE | AD1: PINTAR DE VERDE | AE1: =AE3/4 -> 178 | AF1: MÉDIA P/T | AG1: =AE3/12 -> 59.333333 | AH1: =AE3*2480 -> 1765760 | AT1: =AT2/10 -> 205056
A2: Contrato JACOBINA: | B2: 4600086370 | E2: =E3/B3 -> 0.2371134 | F2: CARTEIRA 2025 | L2: PLANO 14.4.12.1-LPT | M2: LPT DEFINITIVO - ATENDE UC | Q2: VERDE QUANDO | AD2: QUANDO LIGADOS | AE2: =AE3/B3 -> 7.3402062 | AF2: =AF3/AE3 -> 0.68820225 | AG2: =AG3/AE3 -> 0.59129213 | AT2: =AE3*2880 -> 2050560 | AV2: =AE2*2480 -> 18203.711
A3: QTD. OBRAS | B3: =SUBTOTAL(3,B5:B109) -> 97 | E3: 23 | L3: PLANO 14.7.3-LPT | M3: LPT PROVISÓRIO - TEM QUE VALIDAR UC | Q3: CRIADAS | AB3: TOTAIS: | AC3: =SUBTOTAL(9,AC5:AC109) -> 131 | AD3: =SUBTOTAL(9,AD5:AD109) -> 10 | AE3: =SUBTOTAL(9,AE5:AE109) -> 712 | AF3: =SUBTOTAL(9,AF5:AF109) -> 490 | AG3: =SUBTOTAL(9,AG5:AG109) -> 421 | AH3: =SUBTOTAL(9,AH5:AH109) -> 283 | AQ3: MAPA GERAL | AS3: =SUBTOTAL(9,AS5:AS109) -> 3826851.7 | AT3: =SUBTOTAL(9,AT5:AT109) -> 0 | AV3: =AE3*2480 -> 1765760 | AW3: =SUBTOTAL(9,AW5:AW109) -> 4.923 | AX3: =SUBTOTAL(9,AX5:AX109) -> 1.228
A4: NOTA | B4: PEP OBRA | C4: PEP KIT | D4: PEP MED | E4: TÍTULO | F4: MUNICIPIO | G4: STATUS DA OBRA | H4: OBS STATUS | I4: ENCARREGADO | J4: SUPERVISOR | K4: AR COELBA | L4: PLANO INVESTIMENTO | M4: CRITERIO | N4: VISITA PRÉVIA | O4: OBS. VISITA | P4: ANÁLISE PROJETO PRÉ-FECH. | Q4: SOLICITAÇÃO DE RESERVA | R4: DATA SAQUE MATERIAIS | S4: PES LV | T4: VENCIMENTO | U4: PES LM | V4: PES ENERGIZAÇÃO | W4: VENCIMENTO | X4: PES PD | Y4: DATA PD | Z4: STATUS PES PD | AA4: SI PG | AB4: PG's | AC4: CLIENTES PREVISTOS | AD4: QTD. UC'S VALIDADAS LPT | AE4: POSTES PREVISTOS | AF4: CAVA REALIZADA | AG4: POSTES REALIZADO | AH4: POSTES À IMPLANTA | AI4: AVNR | AJ4: AVNP | AK4: INCIO PREVISTO | AL4: FIM PREVISTO | AM4: REPROGRAMAÇÃO FIM | AN4: DATA ENERGIZAÇÃO REAL | AO4: OC DE ENERG. | AP4: PG REFERÊNCIA | AQ4: LATITUDE | AR4: LONGITUDE | AS4: VALOR DE PROJETO | AT4: VALOR DE SERVIÇO | AU4: CÓDIGO EQUIPE | AV4: PROVAVEL ROCHA | AW4: CABO 1B25 | AX4: CABO 3B35 | AY4: OBS | AZ4: AVALIAÇÃO SERVIÇO | BA4: SUBESTAÇÃO ALIMENTADOR | BB4: CHAVE PRINCIPAL | BC4: CHAVE PD | BD4: QTD. UC'S | BE4: VIP | BF4: QTD. H DP | BG4: CHI | BH4: LOCAIS ATINGIDOS | BI4: PG REFERÊNCIA | BJ4: SERVIÇO | BK4: RASCUNHO | BL4: DATA SAQUE MAT. LC | BM4: DATA EXECUÇÃO LC | BN4: TURMA LC | BO4: NÃO ELIMINAR ESTA COLUNA | BP4: NÃO ELIMINAR ESTA COLUNA | BQ4: NÃO ELIMINAR ESTA COLUNA | BR4: PROGRAMAÇÃO LV
A5: 9100059054 | B5: B-0433453 | C5: N/A | D5: N/A | E5: LD - FAZ. QUEIMADAS | F5: BAIXA GRANDE | G5: CANCELADA | H5: OBRA JÁ EXECUTADA ATRAVÉS DO PROJETO Y-0433446 - MP-CCOL-FAZ. QUEIMADAS-RURAL - BAIXA GRANDE | I5: EMERSON DE CARVALHO SILVA - MRA152590 | J5: =VLOOKUP(I5,DADOS!B:F,5,0) -> ETEMILSON OLIVEIRA SANTOS - NTS149530 | K5: MANOEL GUSTAVO OLIVEIRA DOS S CONCEICAO - U464710 | L5: PLANO 7 | M5: QLP | AC5: 1 | AD5: 0 | AE5: 14 | AH5: =AE5-AG5 -> 14 | AI5: =IF(OR(AE5=0, ISERR(AG5/AE5)), 0, AG5/AE5) -> 0 | AS5: 36997.48 | AU5: =VLOOKUP(I5,DADOS!B:C,2,0) -> 2332 | AV5: =AE5*2480 -> 34720 | BG5: =BD5*BF5 -> 0 | BK5: .
A6: 9102372030 | B6: B-1111424 | C6: N/A | D6: N/A | E6: RR-SEIN-FAZ-BARRO VERMELHO-RURAL | F6: BAIXA GRANDE | G6: EM EXECUÇÃO | I6: DIOGO CRUZ DOS SANTOS - MRA177595 | J6: =VLOOKUP(I6,DADOS!B:F,5,0) -> GILVANDO RIOS DA CRUZ - NTS025538 | K6: MANOEL GUSTAVO OLIVEIRA DOS S CONCEICAO - U464710 | L6: PLANO 7 | M6: GOVERNO | N6: 46045 | O6: VISITA REALIZADA 23/01/2026 | P6: 46045 | Q6: 46048 | R6: 46051 | S6: 2026-12214 | T6: 46082 | U6: N/A | V6: 2026-12399 | W6: 46082 | X6: N/A | AA6: 1048338 | AB6: E956402 AO E956411/ E956979 | AC6: 1 | AD6: 0 | AE6: =10+1 -> 11 | AF6: =2+9 -> 11 | AG6: =4+5+1 -> 10 | AH6: =AE6-AG6 -> 1 | AI6: =IF(OR(AE6=0, ISERR(AG6/AE6)), 0, AG6/AE6) -> 0.90909091 | AJ6: 1 | AK6: 46058 | AL6: 46066 | AP6: B933897 | AQ6: -11.991620, | AR6: -40.099284 | AS6: 78172.08 | AU6: =VLOOKUP(I6,DADOS!B:C,2,0) -> 2304 | AV6: =AE6*2480 -> 27280 | BA6: MUN-01N4 2#4 | BB6: W69126 | BG6: =BD6*BF6 -> 0 | BI6: B933897 | BJ6: INTERCALAR POSTE AT COM N1-3 ENTRE OS PG: B933897 - B933898, FECHAR CHAVE NOVA PRÓBIMO AO PG: B933897 E ENERGIZAR OBRA. | BK6: REVISADO APÓS ANÁLISE
A7: 9102126615 | B7: B-1161434 | C7: N/A | D7: N/A | E7: ER-CIND-FAZ-GENIPAPO-RURAL-BAIXA GRANDE | F7: BAIXA GRANDE | G7: EM EXECUÇÃO | I7: DIOGO CRUZ DOS SANTOS - MRA177595 | J7: =VLOOKUP(I7,DADOS!B:F,5,0) -> GILVANDO RIOS DA CRUZ - NTS025538 | K7: MANOEL GUSTAVO OLIVEIRA DOS S CONCEICAO - U464710 | L7: PLANO 7 | M7: LPT | N7: 46045 | O7: VISITA REALIZADA 23/01/2026 | P7: 46045 | Q7: 46048 | R7: 46051 | S7: 2026-12215 | T7: 46082 | U7: N/A | V7: 2026-12400 | W7: 46082 | X7: N/A | AA7: 1048341 | AB7: E956412 AO E956423 | AC7: 1 | AD7: 0 | AE7: 12 | AF7: 7 | AG7: 3 | AH7: =AE7-AG7 -> 9 | AI7: =IF(OR(AE7=0, ISERR(AG7/AE7)), 0, AG7/AE7) -> 0.25 | AJ7: 1 | AK7: 46062 | AL7: 46069 | AP7: B116590 | AQ7: -12.021939 | AR7: -40.189794 | AS7: 111479.61 | AU7: =VLOOKUP(I7,DADOS!B:C,2,0) -> 2304 | AV7: =AE7*2480 -> 29760 | BA7: MUN-01N4 | BB7: N79434 | BG7: =BD7*BF7 -> 0 | BI7: B116590 | BJ7: ALTERAR ESTRUTURA DE N3 P/ N4 NO PG: B116590, FECHAR CHAVE NOVA PRÓBIMO AO PG: B116590 E ENERGIZAR OBRA. | BK7: REVISADO APÓS ANÁLISE
A8: 9102359037 | B8: B-1234711 | C8: B-1243717 | D8: B-1243858 | E8: ER-CIND-POV-CONCEICAO-RURAL | F8: BAIXA GRANDE | G8: EM EXECUÇÃO | I8: DIOGO CRUZ DOS SANTOS - MRA177595 | J8: =VLOOKUP(I8,DADOS!B:F,5,0) -> GILVANDO RIOS DA CRUZ - NTS025538 | K8: MANOEL GUSTAVO OLIVEIRA DOS S CONCEICAO - U464710 | L8: PLANO 14.4.12.1-LPT - ALTERAR P/ 7 | M8: QLP | N8: 46045 | O8: VISITA REALIZADA 23/01/2026 | P8: 46048 | Q8: 46049 | R8: 46058 | S8: 2026-12218 | T8: 46082 | U8: N/A | V8: 2026-12406 | W8: 46082 | X8: 2026-18084 | Y8: 46077 | Z8: APROVADA | AA8: 1048342 | AB8: E956424 AO E956430 | AC8: 1 | AD8: 0 | AE8: 7 | AF8: 1 | AH8: =AE8-AG8 -> 7 | AI8: =IF(OR(AE8=0, ISERR(AG8/AE8)), 0, AG8/AE8) -> 0 | AJ8: 1 | AK8: 46071 | AL8: 46073 | AP8: D217520 | AQ8: -12,024464 | AR8: -40.114233 | AS8: 72581.09 | AU8: =VLOOKUP(I8,DADOS!B:C,2,0) -> 2304 | AV8: =AE8*2480 -> 17360 | BA8: MUN-01N4 | BB8: H80955 | BG8: =BD8*BF8 -> 0 | BI8: D217520 | BJ8: ALTERAR ESTRUTURA DE N1 P/ N4 NO PG: D217520, FECHAR CHAVE NOVA PRÓXIMO AO PG: BBB E ENERGIZAR OBRA. | BK8: REVISADO APÓS ANÁLISE
A9: 9102362042 | B9: B-1235031 | C9: N/A | D9: N/A | E9: ER-SEIN-POV-LASCA GATO-RURAL | F9: BAIXA GRANDE | G9: PROGRAMADA | I9: FABIANO LOPES DE MORAES - MRA554506 | J9: =VLOOKUP(I9,DADOS!B:F,5,0) -> GILVANDO RIOS DA CRUZ - NTS025538 | K9: MANOEL GUSTAVO OLIVEIRA DOS S CONCEICAO - U464710 | L9: PLANO 7 | M9: QLP | N9: 46045 | O9: VISITA REALIZADA 23/01/2026 | P9: 46048 | Q9: 46049 | R9: 46058 | S9: 2026-12226 | T9: 46082 | U9: 2026-12302 | V9: 2026-12411 | W9: 46082 | X9: N/A | AA9: 1048343 | AB9: E956431 AO E956440 | AC9: 1 | AD9: 0 | AE9: 12 | AH9: =AE9-AG9 -> 12 | AI9: =IF(OR(AE9=0, ISERR(AG9/AE9)), 0, AG9/AE9) -> 0 | AJ9: 1 | AK9: 46076 | AL9: 46079 | AP9: E736173 | AQ9: -11,851623 | AR9: -40.218145 | AS9: 114878.17 | AU9: =VLOOKUP(I9,DADOS!B:C,2,0) -> 2326 | AV9: =AE9*2480 -> 29760 | BA9: MUN-01N4 | BB9: E21124 | BG9: =BD9*BF9 -> 0 | BI9: E736173 | BJ9: ALTERAR ESTRUTURA DE N3 P/ N4 NO PG: E736173, SUBSTITUIR POSTE L430520, FECHAR CHAVE NOVA PRÓBIMO AO PG: E736173 E ENERGIZAR OBRA. | BK9: REVISADO APÓS ANÁLISE
A10: 9102363788 | B10: B-1238776 | C10: N/A | D10: N/A | E10: ER-CIND-POV-ITALEGRE 45-RURAL | F10: BAIXA GRANDE | G10: PROGRAMADA | I10: DIOGO CRUZ DOS SANTOS - MRA177595 | J10: =VLOOKUP(I10,DADOS!B:F,5,0) -> GILVANDO RIOS DA CRUZ - NTS025538 | K10: MANOEL GUSTAVO OLIVEIRA DOS S CONCEICAO - U464710 | L10: PLANO 7 | M10: QLP | N10: 46045 | O10: VISITA REALIZADA 23/01/2026 | P10: 46042 | Q10: 46042 | R10: 46051 | S10: 2026-12228 | T10: 46082 | U10: N/A | V10: 2026-12416 | W10: 46082 | X10: N/A | AB10: E894734 | AC10: 1 | AD10: 0 | AE10: 1 | AH10: =AE10-AG10 -> 1 | AI10: =IF(OR(AE10=0, ISERR(AG10/AE10)), 0, AG10/AE10) -> 0 | AJ10: 1 | AK10: 46067 | AL10: 46067 | AP10: B739962 | AQ10: -11.865017 | AR10: -40.243591 | AS10: 11516.45 | AU10: =VLOOKUP(I10,DADOS!B:C,2,0) -> 2304 | AV10: =AE10*2480 -> 2480 | AW10: 0.063 | BA10: MUN-01N4 | BB10: G42012 | BG10: =BD10*BF10 -> 0 | BI10: B739962 | BJ10: INTERCALAR POSTE AT COM N1 ENTRE OS PG: B739962 - B739963, ENCABEÇAR RD BT NO PG: B739962 E ENERGIZAR OBRA. | BK10: REVISADO APÓS ANÁLISE
A11: 9102373521 | B11: B-1240667 | C11: N/A | D11: N/A | E11: ER-CIND-FAZ-SITIO LARANJEIRA-RURAL | F11: BAIXA GRANDE | G11: PROGRAMADA | I11: DIOGO CRUZ DOS SANTOS - MRA177595 | J11: =VLOOKUP(I11,DADOS!B:F,5,0) -> GILVANDO RIOS DA CRUZ - NTS025538 | K11: MANOEL GUSTAVO OLIVEIRA DOS S CONCEICAO - U464710 | L11: PLANO 7 | M11: QLP | N11: 46045 | O11: VISITA REALIZADA 23/01/2026 | P11: 46042 | Q11: 46042 | R11: 46051 | S11: 2026-12231 | T11: 46082 | U11: N/A | V11: 2026-12419 | W11: 46082 | X11: N/A | AB11: E903644 | AC11: 1 | AD11: 0 | AE11: 1 | AH11: =AE11-AG11 -> 1 | AI11: =IF(OR(AE11=0, ISERR(AG11/AE11)), 0, AG11/AE11) -> 0 | AJ11: 1 | AK11: 46067 | AL11: 46067 | AP11: E099562 | AQ11: -11.971381 | AR11: -40.174250 | AS11: 16346.65 | AU11: =VLOOKUP(I11,DADOS!B:C,2,0) -> 2304 | AV11: =AE11*2480 -> 2480 | AW11: 0.063 | BA11: MUN-01N4 | BB11: V01076 | BG11: =BD11*BF11 -> 0 | BI11: E099562 | BJ11: INTERCALAR POSTE AT COM N1 E TRAFO ENTRE OS PG: E099562 - E099563, FECHAR CHAVE NOVA PRÓBIMO AO PG: E099562 E ENERGIZAR OBRA. | BK11: REVISADO APÓS ANÁLISE
A12: 9102360609 | B12: B-1236128 | C12: B-1243671 | D12: B-1243676 | E12: ER-CIND-FAZ-ALGODOES-RURAL-CAEM | F12: CAEM | G12: ENERGIZADA | I12: RODRIGO SANTOS SILVA - MRA096553 | J12: =VLOOKUP(I12,DADOS!B:F,5,0) -> ETEMILSON OLIVEIRA SANTOS - NTS149530 | K12: NATALICIO MENDES DA SILVA - U107662 | L12: PLANO 14.4.12.1-LPT | M12: QLP | N12: 46042 | O12: VISITA REALIZADA 20/01/2026 - EXECUTAR CONFORME PROJETO 02 ADICIONAIS | P12: 46042 | Q12: 46042 | R12: 46052 | S12: 2026-21145 | T12: 46082 | U12: N/A | V12: 2026-12433 | W12: 46082 | X12: N/A | AB12: E930620 AOE930624/E930759AO E930765 | AC12: 2 | AD12: 2 | AE12: =8+4-2 -> 10 | AF12: 10 | AG12: 10 | AH12: =AE12-AG12 -> 0 | AI12: =IF(OR(AE12=0, ISERR(AG12/AE12)), 0, AG12/AE12) -> 1 | AJ12: 1 | AK12: 46055 | AL12: 46063 | AN12: 46066 | AO12: 2026-2-48838 | AP12: D229058 | AQ12: -11.120101 | AR12: -40.079290 | AS12: 90045.29 | AU12: =VLOOKUP(I12,DADOS!B:C,2,0) -> 2300 | AV12: =AE12*2480 -> 24800 | BA12: PON-01B4 | BB12: H84786 | BG12: =BD12*BF12 -> 0 | BI12: D229059 | BJ12: INTERCALAR POSTE AT COM B1-N3 ENTRE OS PG: D229059 - D229058, FECHAR CHAVE NOVA PRÓBIMO AO PG: D229058 E ENERGIZAR OBRA. | BK12: REVISADO APÓS ANÁLISE
A13: 9102361140 | B13: B-1236503 | C13: N/A | D13: N/A | E13: ER-CIND-FAZ-RECANTO-RURAL | F13: CAEM | G13: ENERGIZADA | I13: DOUGLAS DA SILVA MELO - MRA666519 | J13: =VLOOKUP(I13,DADOS!B:F,5,0) -> ETEMILSON OLIVEIRA SANTOS - NTS149530 | K13: NATALICIO MENDES DA SILVA - U107662 | L13: PLANO 7 | M13: QLP | N13: 46042 | O13: VISITA REALIZADA 20/01/2026 - EXECUTAR CONFORME PROJETO | P13: 46043 | Q13: 46043 | R13: 46052 | S13: 2026-12241 | T13: 46082 | U13: N/A | V13: 2026-12436 | W13: 46082 | X13: N/A | AB13: E930679 | AC13: 1 | AD13: 0 | AE13: 1 | AF13: 1 | AG13: 1 | AH13: =AE13-AG13 -> 0 | AI13: =IF(OR(AE13=0, ISERR(AG13/AE13)), 0, AG13/AE13) -> 1 | AJ13: 1 | AK13: 46055 | AL13: 46058 | AN13: 46066 | AO13: 2026-2-49411 | AP13: B667318 | AQ13: -11.164172 | AR13: -40.004242 | AS13: 17263.4 | AU13: =VLOOKUP(I13,DADOS!B:C,2,0) -> 2299 | AV13: =AE13*2480 -> 2480 | BA13: PON-01B4 | BB13: G36611 | BG13: =BD13*BF13 -> 0 | BI13: B667318 | BJ13: INTERCALAR POSTE AT COM N1 E TRAFO ENTRE OS PG: B667318 AO B667317, FECHAR CHAVE NOVA PRÓBIMO AO PG: B667317 E ENERGIZAR OBRA. | BK13: REVISADO APÓS ANÁLISE
A14: 9102365663 | B14: B-1238298 | C14: X-1243672 | D14: X-1243677 | E14: ER-CIND-FAZ-LARANJO-RURAL | F14: CAEM | G14: ENERGIZADA | I14: DOUGLAS DA SILVA MELO - MRA666519 | J14: =VLOOKUP(I14,DADOS!B:F,5,0) -> ETEMILSON OLIVEIRA SANTOS - NTS149530 | K14: NATALICIO MENDES DA SILVA - U107662 | L14: PLANO 7 | M14: QLP | N14: 46042 | O14: VISITA REALIZADA 20/01/2026 - EXECUATAR CONFORME PROJETO | P14: 46043 | Q14: 46043 | R14: 46052 | S14: 2026-12245 | T14: 46082 | U14: N/A | V14: =S14 -> 2026-12245 | W14: 46082 | X14: N/A | AB14: E930678 | AC14: 1 | AD14: 0 | AE14: 1 | AF14: 1 | AG14: 1 | AH14: =AE14-AG14 -> 0 | AI14: =IF(OR(AE14=0, ISERR(AG14/AE14)), 0, AG14/AE14) -> 1 | AJ14: 1 | AK14: 46055 | AL14: 46058 | AN14: 46056 | AO14: 2026-2-9763 | AP14: B861643 | AQ14: -11.076793 | AR14: -40.438206 | AS14: 7821.16 | AU14: =VLOOKUP(I14,DADOS!B:C,2,0) -> 2299 | AV14: =AE14*2480 -> 2480 | BA14: JCB-01M4 | BB14: H57804 | BG14: =BD14*BF14 -> 0 | BI14: D150682 | BJ14: INTERCALAR POSTE AT COM N1 ENTRE OS PG: D150682 - B747115, ENCABEÇAR RD BT NO PG: B861643 E ENERGIZAR OBRA. | BK14: REVISADO APÓS ANÁLISE
A15: 9101786013 | B15: B-1027853 | C15: N/A | D15: N/A | E15: AC-CIND-POV-PATOS-RURAL | F15: CALDEIRÃO GRANDE | G15: ENERGIZADA | I15: RODRIGO SANTOS SILVA - MRA096553 | J15: =VLOOKUP(I15,DADOS!B:F,5,0) -> ETEMILSON OLIVEIRA SANTOS - NTS149530 | K15: NATALICIO MENDES DA SILVA - U107662 | L15: PLANO 7 | M15: QLP OBRAS SIMPLIFICADAS | N15: 46041 | O15: VISITADA PELO ENCARREGADO RODRIGO/ CONFORME PROJETO | P15: 46041 | Q15: 46041 | R15: 46050 | S15: 2026-13278 | T15: 46082 | U15: N/A | V15: 2026-12446 | W15: 46082 | X15: N/A | AB15: E903638 AO E903639 | AC15: 3 | AD15: 0 | AE15: 2 | AF15: 2 | AG15: 2 | AH15: =AE15-AG15 -> 0 | AI15: =IF(OR(AE15=0, ISERR(AG15/AE15)), 0, AG15/AE15) -> 1 | AJ15: 1 | AK15: 46055 | AL15: 46059 | AN15: 46056 | AO15: 2026-2-10979 | AP15: D021106 | AQ15: -10.957561 | AR15: -40.301804 | AS15: 9647.55 | AU15: =VLOOKUP(I15,DADOS!B:C,2,0) -> 2300 | AV15: =AE15*2480 -> 4960 | AW15: 0.063 | BA15: SAU-01L3 | BB15: J51255 | BG15: =BD15*BF15 -> 0 | BI15: D021105 | BJ15: INTERCALAR POSTE AT COM N1 ENTRE OS PG: D021105 - D021106, ENCABEÇAR RD BT NO PG: D021106 E ENERGIZAR OBRA. | BK15: REVISADO APÓS ANÁLISE | BO15: x
A16: 9102148573 | B16: B-1171344 | C16: X-1247853 | D16: X-1248097 | E16: ER-CIND-POV-PATOS-RURAL | F16: CALDEIRÃO GRANDE | G16: ENERGIZADA | I16: RODRIGO SANTOS SILVA - MRA096553 | J16: =VLOOKUP(I16,DADOS!B:F,5,0) -> ETEMILSON OLIVEIRA SANTOS - NTS149530 | K16: NATALICIO MENDES DA SILVA - U107662 | L16: PLANO 7 | M16: LPT OBRAS SIMPLIFICADAS | N16: 46041 | O16: VISITADA PELO ENCARREGADO RODRIGO/ CONFORME PROJETO | P16: 46041 | Q16: 46041 | R16: 46050 | S16: N/A | T16: N/A | U16: N/A | V16: 2026-12341 | W16: 46082 | X16: N/A | AB16: E903640 E E903641 | AC16: 1 | AD16: 0 | AE16: 2 | AF16: 2 | AG16: 2 | AH16: =AE16-AG16 -> 0 | AI16: =IF(OR(AE16=0, ISERR(AG16/AE16)), 0, AG16/AE16) -> 1 | AJ16: 1 | AK16: 46055 | AL16: 46062 | AN16: 46056 | AO16: 2026-2-11124 | AP16: B418593 | AQ16: -10.996459 | AR16: -40.325955 | AS16: 17165.07 | AU16: =VLOOKUP(I16,DADOS!B:C,2,0) -> 2300 | AV16: =AE16*2480 -> 4960 | AW16: 0.124 | BA16: SAU-01L4 | BB16: G12648 | BG16: =BD16*BF16 -> 0 | BI16: B418593 | BJ16: ENCABEÇAR RD BT NO PG: B418593 E ENERGIZAR OBRA. | BK16: REVISADO APÓS ANÁLISE | BO16: x
A17: 9102244607 | B17: B-1201353 | C17: N/A | D17: N/A | E17: ER-COEL-AV-AG ALTO BONITO 99999-RURAL | F17: CALDEIRÃO GRANDE | G17: ENERGIZADA | I17: RODRIGO SANTOS SILVA - MRA096553 | J17: =VLOOKUP(I17,DADOS!B:F,5,0) -> ETEMILSON OLIVEIRA SANTOS - NTS149530 | K17: NATALICIO MENDES DA SILVA - U107662 | L17: PLANO 7 | M17: QLP | N17: 46041 | O17: VISITADA PELO ENCARREGADO RODRIGO/ CONFORME PROJETO | P17: 46041 | Q17: 46041 | R17: 46050 | S17: N/A | T17: N/A | U17: N/A | V17: =X17 -> 2026-10846 | W17: =Y17 -> 46059 | X17: 2026-10846 | Y17: 46059 | Z17: CONCLUÍDA | AB17: E903642 | AC17: 1 | AD17: 0 | AE17: 2 | AF17: 2 | AG17: 2 | AH17: =AE17-AG17 -> 0 | AI17: =IF(OR(AE17=0, ISERR(AG17/AE17)), 0, AG17/AE17) -> 1 | AJ17: 1 | AK17: 46055 | AL17: 46059 | AN17: 46059 | AO17: 2026-2-20648 | AP17: D090571 | AQ17: -11.017373 | AR17: -40.311217 | AS17: 13747.03 | AU17: =VLOOKUP(I17,DADOS!B:C,2,0) -> 2300 | AV17: =AE17*2480 -> 4960 | AX17: 0.033 | BA17: SAU-01L4 | BB17: J58072 | BG17: =BD17*BF17 -> 0 | BI17: D089153 | BJ17: ABRIR CHAVE DO TRAFO: BBB PARA SUBSTITUIR POSTE BT NO PG: D089153, DESATIVAR RD BT DO PG: D090571 AO D089153 E ENERGIZAR OBRA. | BK17: REVISADO APÓS ANÁLISE
A18: 9102361417 | B18: B-1240780 | C18: N/A | D18: N/A | E18: ER-CIND-FAZ-AGUA BOA-RURAL | F18: CAPIM GROSSO | G18: ENERGIZADA | I18: CAIQUE SILVA LIMA - MRA219559 | J18: =VLOOKUP(I18,DADOS!B:F,5,0) -> GILVANDO RIOS DA CRUZ - NTS025538 | K18: RAFAEL SANTOS DA CRUZ - U469504 | L18: PLANO 7 | M18: QLP | P18: 46042 | Q18: 46043 | R18: 46051 | S18: N/A | T18: N/A | U18: N/A | V18: 2026-12345 | W18: 46082 | X18: N/A | AB18: E903645 | AC18: 1 | AD18: 0 | AE18: 1 | AF18: 1 | AG18: 1 | AH18: =AE18-AG18 -> 0 | AI18: =IF(OR(AE18=0, ISERR(AG18/AE18)), 0, AG18/AE18) -> 1 | AJ18: 1 | AK18: 46060 | AL18: 46060 | AN18: 46058 | AO18: 2026-2-17620 | AP18: E310221 | AQ18: -11.360173 | AR18: -40.043791 | AS18: 5287.2 | AU18: =VLOOKUP(I18,DADOS!B:C,2,0) -> 2381 | AV18: =AE18*2480 -> 2480 | AW18: 0.063 | BA18: JCB-09N3 | BB18: V20645 | BG18: =BD18*BF18 -> 0 | BI18: E310221 | BJ18: ENCABEÇAR RD BT NO PG: E310221 E ENERGIZAR OBRA. | BK18: REVISADO APÓS ANÁLISE
A19: 9102359457 | B19: B-1240846 | C19: N/A | D19: N/A | E19: ER-CIND-FAZ-VARZEA DA CABRA-RURAL | F19: CAPIM GROSSO | G19: ENERGIZADA | I19: CAIQUE SILVA LIMA - MRA219559 | J19: =VLOOKUP(I19,DADOS!B:F,5,0) -> GILVANDO RIOS DA CRUZ - NTS025538 | K19: RAFAEL SANTOS DA CRUZ - U469504 | L19: PLANO 7 | M19: QLP | P19: 46042 | Q19: 46043 | R19: 46051 | S19: N/A | T19: N/A | U19: N/A | V19: 2026-12348 | W19: 46082 | X19: N/A | AB19: E903646 ao E903648 | AC19: 1 | AD19: 0 | AE19: 3 | AF19: 3 | AG19: 3 | AH19: =AE19-AG19 -> 0 | AI19: =IF(OR(AE19=0, ISERR(AG19/AE19)), 0, AG19/AE19) -> 1 | AJ19: 1 | AK19: 46060 | AL19: 46062 | AN19: 46058 | AO19: 2026-2-17169 | AP19: E337158 | AQ19: -11.359693 | AR19: -40.028273 | AS19: 16733.26 | AU19: =VLOOKUP(I19,DADOS!B:C,2,0) -> 2381 | AV19: =AE19*2480 -> 7440 | AW19: 0.185 | BA19: CGI-01F2 | BB19: G07847 | BG19: =BD19*BF19 -> 0 | BI19: E337158 | BJ19: ENCABEÇAR RD BT NO PG: E337158 E ENERGIZAR OBRA. | BK19: REVISADO APÓS ANÁLISE
A20: 9102355789 | B20: B-1237699 | C20: N/A | D20: N/A | E20: ER-CIND-RUA-DAS FLORES-VARZEA DA LAGE | F20: JACOBINA | G20: ENERGIZADA | I20: RODRIGO SANTOS SILVA - MRA096553 | J20: =VLOOKUP(I20,DADOS!B:F,5,0) -> ETEMILSON OLIVEIRA SANTOS - NTS149530 | K20: RICARDO SANTOS DE BRITO - U465100 | L20: PLANO 7 | M20: QLP | N20: 46044 | O20: VISITA REALIZADA - EXECUTAR CONFORME PROJETO | P20: 46044 | Q20: 46048 | R20: 46057 | S20: N/A | T20: N/A | U20: N/A | V20: 2026-17542 | W20: =Y20 | X20: N/A | Z20: CANCELADA | AB20: E956586 AO E956588 E956620 ao E956622 | AC20: 1 | AD20: 0 | AE20: 6 | AF20: 6 | AG20: 6 | AH20: =AE20-AG20 -> 0 | AI20: =IF(OR(AE20=0, ISERR(AG20/AE20)), 0, AG20/AE20) -> 1 | AJ20: 1 | AK20: 46055 | AL20: 46058 | AN20: 46057 | AO20: 2026-2-14656 | AP20: B916916 | AQ20: -11.223105 | AR20: -40.412976 | AS20: 16374.58 | AU20: =VLOOKUP(I20,DADOS!B:C,2,0) -> 2300 | AV20: =AE20*2480 -> 14880 | AW20: 0.21 | BA20: JCB-01M5 | BB20: J04397 | BG20: =BD20*BF20 -> 0 | BI20: R016254 | BJ20: ENCABEÇAR RD BT NO PG: B916916 E ENERGIZAR OBRA. | BK20: REVISADO APÓS ANÁLISE
A21: 9102371542 | B21: B-1240598 | C21: N/A | D21: N/A | E21: ER-CIND-FAZ-FONTE DO BENEDITO 12-CACHOEI | F21: JACOBINA | G21: ENERGIZADA | I21: RODRIGO SANTOS SILVA - MRA096553 | J21: =VLOOKUP(I21,DADOS!B:F,5,0) -> ETEMILSON OLIVEIRA SANTOS - NTS149530 | K21: RICARDO SANTOS DE BRITO - U465100 | L21: PLANO 7 | M21: QLP | N21: 46044 | O21: VISITA REALIZADA - EXECUTAR CONFORME PROJETO | P21: 46044 | Q21: 46048 | R21: 46057 | S21: N/A | T21: N/A | U21: N/A | V21: 2026-12357 | W21: 46082 | X21: N/A | AB21: E918328 e E918329 | AC21: 1 | AD21: 0 | AE21: 2 | AF21: 2 | AG21: 2 | AH21: =AE21-AG21 -> 0 | AI21: =IF(OR(AE21=0, ISERR(AG21/AE21)), 0, AG21/AE21) -> 1 | AJ21: 1 | AK21: 46063 | AL21: 46063 | AN21: 46056 | AO21: 2026-2-11359 | AP21: R017277 | AQ21: -11.343264 | AR21: -40.414341 | AS21: 11593.74 | AU21: =VLOOKUP(I21,DADOS!B:C,2,0) -> 2300 | AV21: =AE21*2480 -> 4960 | AW21: 0.156 | BA21: JCB-01M5 | BB21: J04038 | BG21: =BD21*BF21 -> 0 | BI21: B107042 | BJ21: ENCABEÇAR RD BT NO PG: B107042 E ENERGIZAR OBRA. | BK21: REVISADO APÓS ANÁLISE
A22: 9102364909 | B22: B-1240857 | C22: N/A | D22: N/A | E22: ER-CIND-POV-ANGICO 888-RURAL | F22: MAIRI | G22: ENERGIZADA | I22: FABIANO LOPES DE MORAES - MRA554506 | J22: GILVANDO RIOS DA CRUZ - NTS025538 | K22: MANOEL GUSTAVO OLIVEIRA DOS S CONCEICAO - U464710 | L22: PLANO 7 | M22: QLP | P22: 46049 | Q22: 46051 | R22: 46058 | S22: C/ DP | T22: N/A | U22: N/A | V22: =X22 -> 2026-10814 | W22: =Y22 -> 46065 | X22: 2026-10814 | Y22: 46065 | Z22: APROVADA | AA22: 1048348 | AB22: E956441 AO E956449 | AC22: 1 | AD22: 0 | AE22: 9 | AF22: 9 | AG22: =7+2 -> 9 | AH22: =AE22-AG22 -> 0 | AI22: =IF(OR(AE22=0, ISERR(AG22/AE22)), 0, AG22/AE22) -> 1 | AJ22: 1 | AK22: 46058 | AL22: 46065 | AN22: 46065 | AO22: 2026-2-44296 | AP22: E585411 | AQ22: -11.668491 | AR22: -40.292241 | AS22: 62721.97 | AU22: =VLOOKUP(I22,DADOS!B:C,2,0) -> 2326 | AV22: =AE22*2480 -> 22320 | BA22: MUN-01N6 | BB22: D03773 | BG22: =BD22*BF22 -> 0 | BI22: E585412 | BJ22: ABRIR CHAVE: D03773 PARA, SUBSTITUIR POSTES BT POR AT DO PG: E585412 AO E664653, REALOCAR TRAFO: D03781 PARA POSTE PG: E664653 E ENERGIZAR OBRA. | BK22: REVISADO APÓS ANÁLISE
A23: 9102369238 | B23: B-1241023 | C23: N/A | D23: N/A | E23: IP-PREF-RUA-ALTO DA BOA VISTA -RURAL | F23: MAIRI | G23: ENERGIZADA | I23: FABIANO LOPES DE MORAES - MRA554506 | J23: GILVANDO RIOS DA CRUZ - NTS025538 | K23: MANOEL GUSTAVO OLIVEIRA DOS S CONCEICAO - U464710 | L23: PLANO 7 | M23: QLP | P23: 46043 | Q23: 46044 | R23: 46051 | S23: N/A | T23: N/A | U23: N/A | V23: =X23 -> 2026-12006 | W23: =Y23 -> 46064 | X23: 2026-12006 | Y23: 46064 | Z23: APROVADA | AB23: E930680 E E930681 | AC23: 1 | AD23: 0 | AE23: 2 | AF23: 2 | AG23: 2 | AH23: =AE23-AG23 -> 0 | AI23: =IF(OR(AE23=0, ISERR(AG23/AE23)), 0, AG23/AE23) -> 1 | AJ23: 1 | AK23: 46057 | AL23: 46060 | AN23: 46064 | AO23: 2026-2-40761 | AP23: D359201 | AQ23: -11.668960 | AR23: -40.290484 | AS23: 11267.31 | AU23: =VLOOKUP(I23,DADOS!B:C,2,0) -> 2326 | AV23: =AE23*2480 -> 4960 | BA23: MUN-01N6 | BB23: T21022 | BG23: =BD23*BF23 -> 0 | BI23: L440460 | BJ23: ABRIR CHAVE: T21022 P/ INTRECALAR POSTE BT ENTRE OS PG: L440460 - L440471, ENCABEÇAR RD BT NO PG: L440471 E ENERGIZAR OBRA. | BK23: REVISADO APÓS ANÁLISE
A24: 9102356472 | B24: B-1239926 | C24: N/A | D24: N/A | E24: ER-CIND-POV CURRAL VELHO-RURAL | F24: MIGUEL CALMON | G24: ENERGIZADA | I24: EMERSON DE CARVALHO SILVA - MRA152590 | J24: =VLOOKUP(I24,DADOS!B:F,5,0) -> ETEMILSON OLIVEIRA SANTOS - NTS149530 | K24: NAILTON SANTANA PEREIRA FILHO - U344575 | L24: PLANO 7 | M24: QLP | N24: 46042 | O24: EXECUTAR CONFORME PROJETO / OBRA VISITADA | P24: 46043 | Q24: 46043 | R24: 46052 | S24: 2026-12250 | T24: 46082 | U24: N/A | V24: 2026-12447 | W24: 46082 | X24: N/A | AB24: E903649 E E903650 | AC24: 1 | AD24: 0 | AE24: 2 | AF24: 2 | AG24: 2 | AH24: =AE24-AG24 -> 0 | AI24: =IF(OR(AE24=0, ISERR(AG24/AE24)), 0, AG24/AE24) -> 1 | AJ24: 1 | AK24: 46055 | AL24: 46056 | AN24: 46056 | AO24: 2026-2-10388 | AP24: E673923 | AQ24: -11.289350 | AR24: -40.627003 | AS24: 20542.18 | AU24: =VLOOKUP(I24,DADOS!B:C,2,0) -> 2332 | AV24: =AE24*2480 -> 4960 | AW24: 0.063 | BA24: MCM-01J4 | BB24: D08573 | BG24: =BD24*BF24 -> 0 | BI24: E673923 | BJ24: INTERCALAR POSTE AT COM N1 E TRAFO ENTRE OS PG: E673923 - E673924, FECHAR CHAVE NOVA PRÓBIMO AO PG: E673923 E ENERGIZAR OBRA. | BK24: REVISADO APÓS ANÁLISE
A25: 9101089006 | B25: B-0823651 | E25: LD CIND POV FORMOSA RURAL | F25: MIGUEL CALMON | G25: CANCELADA | H25: OBRA JÁ EXECUTADA ATRAVÉS DO PROJETO Y-0895944 - UB-CIND-RUA JOS LUCIO-CENTRO-MGC - MIGUEL CALMON | I25: RODRIGO SANTOS SILVA - MRA096553 | J25: =VLOOKUP(I25,DADOS!B:F,5,0) -> ETEMILSON OLIVEIRA SANTOS - NTS149530 | K25: NAILTON SANTANA PEREIRA FILHO - U344575 | L25: PLANO 14.7.3-LPT | M25: LPT | N25: 45674 | O25: VISITADA PELO ENCARREGADO. | P25: FVP - 17/12/25 | U25: N/A | X25: N/A | AC25: 1 | AE25: 10 | AH25: =AE25-AG25 -> 10 | AI25: =IF(OR(AE25=0, ISERR(AG25/AE25)), 0, AG25/AE25) -> 0 | AP25: D537100 | AQ25: -11,427731 | AR25: -40,607950 | AS25: 42629.54 | AU25: =VLOOKUP(I25,DADOS!B:C,2,0) -> 2300 | AV25: =AE25*2480 -> 24800 | BA25: MCM-01J1 3#4 | BB25: J03454 | BG25: =BD25*BF25 -> 0 | BI25: D537100 | BJ25: MONTAR BANCADA COM N3 NO PG: D537100, FECHAR CHAVE NOVA PRÓBIMO AO PG: D537100 E ENERGIZAR OBRA. | BK25: .
A26: 9102355682 | B26: B-1236062 | C26: N/A | D26: N/A | E26: ER-CIND-FAZ-IPUEIRA DO SABIA-III 112 | F26: MUNDO NOVO | G26: EM EXECUÇÃO | I26: CARLOS DA CRUZ SANTANA - MRA258541 | J26: =VLOOKUP(I26,DADOS!B:F,5,0) -> ETEMILSON OLIVEIRA SANTOS - NTS149530 | K26: NAILTON SANTANA PEREIRA FILHO - U344575 | L26: PLANO 7 | M26: QLP | P26: 46050 | Q26: 46050 | R26: 46057 | S26: 2026-21170 | T26: 46082 | U26: N/A | V26: 2026-12461 | W26: 46082 | X26: N/A | AA26: 1048350 | AB26: E956450 AO E956459 | AC26: 1 | AD26: 0 | AE26: 10 | AF26: 10 | AG26: 9 | AH26: =AE26-AG26 -> 1 | AI26: =IF(OR(AE26=0, ISERR(AG26/AE26)), 0, AG26/AE26) -> 0.9 | AJ26: 1 | AK26: 46055 | AL26: 46062 | AP26: L398204 | AQ26: -11.763451 | AR26: -40.425355 | AS26: 78903.84 | AU26: =VLOOKUP(I26,DADOS!B:C,2,0) -> 2349 | AV26: =AE26*2480 -> 24800 | AW26: 0.063 | BA26: MUN-01N5 | BB26: DJ:J03289 | BG26: =BD26*BF26 -> 0 | BI26: L398206 | BJ26: INTERCALAR POSTE AT COM N1-3 ENTRE OS PG: L398206 - L398204, FECHAR CHAVE NOVA PRÓBIMO AO PG: L398206 E ENERGIZAR OBRA. | BK26: REVISADO APÓS ANÁLISE
A27: 9102052168 | B27: B-1137720 | E27: ER-CIND-POV-LAGEDO-RURAL | F27: CAPIM GROSSO | G27: RETIRADA DA CARTEIRA | H27: DIRECIONADA PARA EPS DÍNAMO | I27: CAIQUE SILVA LIMA - MRA219559 | J27: =VLOOKUP(I27,DADOS!B:F,5,0) -> GILVANDO RIOS DA CRUZ - NTS025538 | L27: PLANO 14.4.12.1-LPT | M27: LPT | P27: 46051 | Q27: 46051 | S27: N/A | U27: N/A | V27: 2026-14484 | X27: N/A | AB27: E956629 AO E956632 | AC27: 1 | AE27: 4 | AH27: =AE27-AG27 -> 4 | AI27: =IF(OR(AE27=0, ISERR(AG27/AE27)), 0, AG27/AE27) -> 0 | AJ27: 1 | AP27: E474676 | AQ27: -11,313755 | AR27: -40,038778 | AS27: 24831.28 | AU27: =VLOOKUP(I27,DADOS!B:C,2,0) -> 2381 | AV27: =AE27*2480 -> 9920 | AW27: 0.25 | BA27: CGI-01F1 | BB27: V45697 | BG27: =BD27*BF27 -> 0 | BI27: E474676 | BJ27: ENCABEÇAR RD BT NO PG: E474676 E ENERGIZAR OBRA. | BK27: .
A28: 9102338765 | B28: B-1226969 | C28: N/A | D28: N/A | E28: ER-CIND-SI-VOVO ZEZE-MUNDO NOVO | F28: MUNDO NOVO | G28: ENERGIZADA | I28: CARLOS DA CRUZ SANTANA - MRA258541 | J28: =VLOOKUP(I28,DADOS!B:F,5,0) -> ETEMILSON OLIVEIRA SANTOS - NTS149530 | K28: NAILTON SANTANA PEREIRA FILHO - U344575 | L28: PLANO 7 | M28: QLP | P28: 46008 | Q28: 19/12/25 - RE 07/01/26 | R28: 46050 | S28: 2026-12261 | T28: 46082 | U28: N/A | V28: 2026-12467 | W28: 46082 | X28: N/A | AB28: E852101 AO E852103 | AC28: 1 | AD28: 0 | AE28: 3 | AF28: 3 | AG28: 3 | AH28: 0 | AI28: 0 | AJ28: 1 | AK28: 46039 | AL28: 46057 | AN28: 46064 | AO28: 2026-2-42464 | AP28: L432383 | AQ28: -11,867991 | AR28: -40,439564 | AS28: 39472.1 | AU28: 2381 | AV28: 7440 | BA28: MUN-01N4 3#4 | BB28: T16242 | BG28: 0 | BI28: L432383 | BJ28: MONTAR BANCADA COM N3 NO PG: L432383, FECHAR CHAVE NOVA PRÓBIMO AO PG: L432383 E ENERGIZAR OBRA. | BK28: REVISADO APÓS ANÁLISE
A29: 9102359580 | B29: B-1235320 | C29: N/A | D29: N/A | E29: ER-CIND-POV-TAPIRANGA 500-RR-TAPIRANGA | F29: MIGUEL CALMON | G29: ENERGIZADA | I29: EMERSON DE CARVALHO SILVA - MRA152590 | J29: ETEMILSON OLIVEIRA SANTOS - NTS149530 | K29: NAILTON SANTANA PEREIRA FILHO - U344575 | L29: PLANO 7 | M29: QLP | N29: 46008 | P29: 46038 | Q29: 46041 | R29: 46050 | S29: 2026-12262 | T29: 46082 | U29: N/A | V29: 2026-12479 | W29: 46082 | X29: N/A | AB29: E920022 AO E920033 | AC29: 1 | AD29: 0 | AE29: 12 | AF29: 12 | AG29: 12 | AH29: =AE29-AG29 -> 0 | AI29: 0 | AJ29: 1 | AK29: 46028 | AL29: 46058 | AN29: 46056 | AO29: 2026-2-11427 | AP29: R040683 | AQ29: -11,451460 | AR29: -40,411330 | AS29: 132499.92 | AU29: 2332 | AV29: 29760 | AW29: 0.11 | BA29: MCM-01J2 | BB29: W70427 | BG29: 0 | BI29: R040683 | BJ29: INTERCALAR POSTE AT COM N1-3 ENTRE OS PG: R040683 - R040682, FECHAR CHAVE NOVA PRÓBIMO AO PG: R040683 E ENERGIZAR OBRA. | BK29: REVISADO APÓS ANÁLISE | BO29: Aguardando revisão de orcamento
A30: 9102355339 | B30: B-1238642 | C30: N/A | D30: N/A | E30: ER-CIND-POV VARZEA DE FORA-RURAL | F30: OUROLÂNDIA | G30: ENERGIZADA | I30: CLEBSON REIS NETO - MRA148601 | J30: =VLOOKUP(I30,DADOS!B:F,5,0) -> ETEMILSON OLIVEIRA SANTOS - NTS149530 | K30: ERIC TEIXEIRA OLIVEIRA BARBOSA - U361045 | L30: PLANO 7 | M30: QLP | N30: 46041 | P30: 46041 | Q30: 46042 | R30: 46052 | S30: N/A | T30: N/A | U30: N/A | V30: 2026-12365 | W30: 46082 | X30: N/A | AB30: E877204 AO E877207 | AC30: 1 | AD30: 0 | AE30: 4 | AF30: 4 | AG30: 4 | AH30: =AE30-AG30 -> 0 | AI30: =IF(OR(AE30=0, ISERR(AG30/AE30)), 0, AG30/AE30) -> 1 | AJ30: 1 | AK30: 46055 | AL30: 46056 | AN30: 46055 | AO30: 2026-2-6893 | AP30: R028897 | AQ30: -11.018339 | AR30: -41.109615 | AS30: 19010.72 | AU30: =VLOOKUP(I30,DADOS!B:C,2,0) -> 2303 | AV30: =AE30*2480 -> 9920 | AW30: 0.25 | BA30: JCB-09N4 | BB30: J04007 | BG30: =BD30*BF30 -> 0 | BI30: R028897 | BJ30: ENCABEÇAR RD BT NO PG: R028897 E ENERGIZAR OBRA. | BK30: REVISADO APÓS ANÁLISE
A31: 9102361504 | B31: B-1234938 | C31: N/A | D31: N/A | E31: ER-CIND-FAZ-VARZEA DO PEDRO-RURAL | F31: SAÚDE | G31: EM EXECUÇÃO | H31: ABRIR OC DE ENERGIZAÇÃO DIA 16/02 | I31: DOUGLAS DA SILVA MELO - MRA666519 | J31: =VLOOKUP(I31,DADOS!B:F,5,0) -> ETEMILSON OLIVEIRA SANTOS - NTS149530 | K31: NATALICIO MENDES DA SILVA - U107662 | L31: PLANO 7 | M31: QLP | N31: 46041 | O31: EXECUTAR CONFOR PROJETO | P31: 46042 | Q31: 46042 | R31: 46052 | S31: 2026-12266 | T31: 46082 | U31: N/A | V31: 2026-12480 | W31: 46082 | X31: N/A | Z31: CANCELADA | AA31: 1048351 | AB31: E956460 AO E956481 | AC31: 2 | AD31: 0 | AE31: =22+1 -> 23 | AF31: 15 | AG31: 15 | AH31: 0 | AI31: =IF(OR(AE31=0, ISERR(AG31/AE31)), 0, AG31/AE31) -> 0.65217391 | AJ31: 1 | AK31: 46057 | AL31: 46070 | AP31: D778089 | AQ31: -11.016102 | AR31: -40.399589 | AS31: 203331.72 | AU31: =VLOOKUP(I31,DADOS!B:C,2,0) -> 2299 | AV31: =AE31*2480 -> 57040 | AW31: 0.22 | BA31: SAU-01L2 | BB31: N81161 | BG31: =BD31*BF31 -> 0 | BI31: D778089 | BJ31: ALTERAR ESTRUTURA DE N3 P/ N4 NO PG: D778089, FECHAR CHAVE NOVA PRÓBIMO AO PG: D778089 E ENERGIZAR OBRA. | BK31: REVISADO APÓS ANÁLISE
A32: 9102364490 | B32: B-1240504 | C32: N/A | D32: N/A | E32: AC-CIND-RUA-LAURO TEIXEIRA-PECUARIA | F32: SAÚDE | G32: ENERGIZADA | I32: DOUGLAS DA SILVA MELO - MRA666519 | J32: =VLOOKUP(I32,DADOS!B:F,5,0) -> ETEMILSON OLIVEIRA SANTOS - NTS149530 | K32: NATALICIO MENDES DA SILVA - U107662 | L32: PLANO 7 | M32: QLP | N32: 46041 | O32: EXECUTAR CONFOR PROJETO | P32: 46041 | Q32: 46049 | R32: 46057 | S32: N/A | T32: N/A | U32: N/A | V32: 2026-12381 | W32: 46082 | X32: N/A | AB32: E930601 | AC32: 1 | AD32: 0 | AE32: 1 | AF32: 1 | AG32: 1 | AH32: =AE32-AG32 -> 0 | AI32: =IF(OR(AE32=0, ISERR(AG32/AE32)), 0, AG32/AE32) -> 1 | AJ32: 1 | AK32: 46055 | AL32: 46056 | AN32: 46056 | AO32: 2026-2-11435 | AP32: B763290 | AQ32: -10.949047 | AR32: -40.421957 | AS32: 7792.49 | AU32: =VLOOKUP(I32,DADOS!B:C,2,0) -> 2299 | AV32: =AE32*2480 -> 2480 | AW32: 0.052 | BA32: SAU-01L2 | BB32: N43355 | BG32: =BD32*BF32 -> 0 | BI32: B763290 | BJ32: ENCABEÇAR RD BT NO PG: B763290 E ENERGIZAR OBRA. | BK32: REVISADO APÓS ANÁLISE
A33: 9102354346 | B33: B-1234334 | C33: B-1242660 | D33: B-1242662 | E33: ER-CIND-TRV-MANOEL MACIEL-ROCADINHO | F33: SERROLÂNDIA | G33: ENERGIZADA | I33: LUCIANO NUNES DA SILVA - MRA252517 | J33: =VLOOKUP(I33,DADOS!B:F,5,0) -> GILVANDO RIOS DA CRUZ - NTS025538 | K33: RAFAEL SANTOS DA CRUZ - U469504 | L33: PLANO 14.4.12.1-LPT | M33: QLP | N33: 46044 | O33: VISITA REALIZADA 22/01/2026 | P33: 46044 | Q33: 46049 | R33: 46058 | S33: 2026-12274 | T33: 46082 | U33: N/A | V33: 2026-12485 | W33: 46082 | X33: N/A | AA33: 1048354 | AB33: E956482 AO E956491 | AC33: =1+1 -> 2 | AD33: 2 | AE33: 10 | AF33: 10 | AG33: =6+3+1 -> 10 | AH33: =AE33-AG33 -> 0 | AI33: =IF(OR(AE33=0, ISERR(AG33/AE33)), 0, AG33/AE33) -> 1 | AJ33: 1 | AK33: 46058 | AL33: 46066 | AN33: 46066 | AO33: 2026-2-47953 | AP33: B645742 | AQ33: -11.374587 | AR33: -40.330970 | AS33: 75307.7 | AU33: =VLOOKUP(I33,DADOS!B:C,2,0) -> 2305 | AV33: =AE33*2480 -> 24800 | BA33: SRL-01P1 | BB33: G44373 | BG33: =BD33*BF33 -> 0 | BI33: B645743 | BJ33: INTERCALAR POSTE AT COM N1 E TRAFO, ENTRE OS PG: B645743 - B645742, FECHAR CHAVE NOVA PRÓBIMO AO PG: B645742 E ENERGIZAR OBRA. | BK33: REVISADO APÓS ANÁLISE
A34: 9102365044 | B34: B-1236459 | C34: N/A | D34: N/A | E34: ER-CIND-RUA-DEOCLECIANO MELLO -SALAMIM | F34: SERROLÂNDIA | G34: EM EXECUÇÃO | H34: MELHORAMENTO | I34: LUCIANO NUNES DA SILVA - MRA252517 | J34: =VLOOKUP(I34,DADOS!B:F,5,0) -> GILVANDO RIOS DA CRUZ - NTS025538 | K34: RAFAEL SANTOS DA CRUZ - U469504 | L34: PLANO 7 | M34: QLP | N34: 46044 | O34: VISITA REALIZADA 22/01/2026 | P34: 46044 | Q34: 46049 | R34: 46058 | S34: C/ DP | T34: N/A | U34: 2026-12306 | V34: =X34 -> 2026-20365 | W34: =Y34 -> 46079 | X34: 2026-20365 | Y34: 46079 | Z34: APROVADA | AA34: 1048356 | AB34: E956492 AO E956501 | AC34: 1 | AD34: 0 | AE34: 10 | AF34: 7 | AG34: 7 | AH34: =AE34-AG34 -> 3 | AI34: =IF(OR(AE34=0, ISERR(AG34/AE34)), 0, AG34/AE34) -> 0.7 | AJ34: 1 | AK34: 46057 | AL34: 46063 | AP34: R000942 | AQ34: -11.351447 | AR34: -40.275503 | AS34: 127629.54 | AU34: =VLOOKUP(I34,DADOS!B:C,2,0) -> 2305 | AV34: =AE34*2480 -> 24800 | BA34: JCB-09N3 | BB34: J02166 | BG34: =BD34*BF34 -> 0 | BI34: R000939 | BJ34: ABRIR CHAVE: J02166 PARA SUBST. PT AT NO PG: R000939, SUBST. PTS. BT POR AT DO PG: R000940 AO R000941, SUBST. RD BT DO PG: R000941 AO R000938 AO R000942 E ENERGIZAR OBRA. | BK34: REVISADO APÓS ANÁLISE
